Workbook

Sheet VALORI
A1: COSTO MANODOPERA | E1: NORMATIVE
A3: Costo Orario Attività Studio Elettromeccanico | B3: 37 | E3: CE | F3: Piano Normativo di riferimento - CE
A4: Costo Orario Attività Studio Software | B4: 38 | E4: UL | F4: Piano Normativo di riferimento - UL
A5: Costo Orario Attività Costruzione Elettromeccanica | B5: 29 | E5: NR | F5: Piano Normativo di riferimento - NR
A6: Costo Orario Attività Collaudo Elettromeccanico | B6: 29
A7: Costo Orario Attività Collaudo Software | B7: 38

Sheet REVISIONI
A1: GESTIONE REVISIONI
A2: DATA DOCUMENTO | B2: REVISIONE | C2: DATA REVISIONE | D2: DESCRIZIONE
A3: 2022 03 15 | D3: Emissione Definitiva Listino QE a UT e OTE
A4: 2022 05 23 | B4: 00 | C4: 44704 | D4: Creata Scheda per Linee ROMET 3500 Kg/h
A5: 2022 05 23 | B5: 01 | C5: 44706 | D5: Creato modello "Sili Pasta Lunga" - Silo con 7 piani e sfilatrice singola
A6: 2022 05 23 | B6: 02 | C6: 44708 | D6: Incrementato "SILI PASTA CORTA" - "1 Battieria 5-6 S Sili" - "Tempo Costruzione QE" da 100 a 120 Ore perche valutazioni iniziale troppo stretta.
A7: 2022 05 23 | B7: 03 | C7: 44708 | D7: Incrementato "PASTA LUNGA - ITRG270" - "Produzione 2200Kg/h" - "Tempo Collaudo QE" da 40 a 50 Ore perche non corretto rispetto il teorico del 10-12% del tempo di costruzione
A8: 2022 05 23 | B8: 04 | C8: 44708 | D8: Incrementato "SILO LUNGA - ITRG270" - "Produzione 2200Kg/h" - "Tempo Collaudo QE" da 40 a 50 Ore perche non corretto rispetto il teorico del 10-12% del tempo di costruzione
A9: 2022 05 23 | B9: 05 | C9: 44726 | D9: Creata Scheda per Linee ROMET 6000 Kg/h
A10: 2022 05 23 | B10: 06 | C10: 44732 | D10: Inserita Opzione "Espulsione Aria Trabatto comandata con Inverter" su PASTA CORTA - ECOCSYSTEM e PASTA CORTA - TCM100
A11: 2022 05 23 | B11: 07 | C11: 44748 | D11: Inserita Opzione "Lama D'Aria Ingresso Trabatto" su PASTA CORTA - ECOCSYSTEM, PASTA CORTA - TCM100 e PASTA CORTA - ROMET
A12: 2022 05 23 | B12: 08 | C12: 44748 | D12: Incrementato Costo Materiali Standard del 10% a partire dal 20/06/2022 a seguito comunicazione SIEMENS
A13: 2023 05 23 | B13: 09 | C13: 44776 | D13: Incrementato Costo Materiali del 20% dell'opzione relativa al comando delle ventilazioni essiccatoio con inverter nelle linee CTA, a seguito comunicazione SIEMENS
A14: 2022 05 23 | B14: 10 | C14: 44805 | D14: Aggiornamento descrizione ROMET da 24/9DV a 24/8HT per la linea da 1200 Kg. Il costo del materiale incrementa di 6KEuro a causa dell'utilizzo dell'inverter
A15: 2022 05 23 | B15: 11 | C15: 44888 | D15: Aumentato costo sistema di 4 telecamere per controllo ambientale sulle linee di produzione da 6000 a 8000 Euro a seguito incremento costo materiali.
... A18: 2022 12 02 | B18: 14 | C18: 44888 | D18: Inserito OPZIONE Raffreddamento Olio Riduttori Viti
A19: 2023 03 01 | D19: Emissione Listino QE a UT e OTE Versione 2023-03
A21: 2023 01 15 | B21: 01 | C21: 45027 | D21: Incementato tempo costruzione sili polmone con sfilatrice singola di 20h causa applicazione box a bordo sfilatrice
A22: 2023 01 15 | B22: 02 | C22: 45272 | D22: Incrementato costo materiali per sili pasta corta e pasta lunga per allineamento a media consuntivi
A23: 2023 01 15 | B23: 03 | C23: 45272 | D23: Incremento costo materiali di 3% causa incfremento costo materiali da SIEMENS
A24: 2023 01 15 | B24: 04 | C24: 45272 | D24: Incrementato differenza tra materiale CE e Materiale UL dal 15% al 20% causa cambio sconti per acquisti troppo limitati
A26: 2024 02 12 | D26: Emissione Listino QE a UT e OTE Versione 2024-02
A27: 2024 02 12 | B27: 01 | C27: 45331 | D27: Aggiornamento costo materiali come da indicazione SIEMENS7
A28: 2024 02 12 | B28: 02 | C28: 45484 | D28: Incrementato le ore di cablaggio dei sili pasta lunga di 20h a causa del cablaggio del nuovo quadro a bordo sfilatrice. (Aumento qualità da collaudo completo interno)
A29: 2024 02 12 | B29: 03 | C29: 45503 | D29: Inserito Opzionali relativi a Motorizzazioni a doppia polarita, bypass idraulici con doppia valvola e ventilazione riscaldata sotto trafila per le linee pasta corta

Sheet PASTA CORTA - ECOSYSTEM
B1: PASTA CORTA - TCM ECOSYSTEM | X1: OPZIONE | Y1: OPZIONE | Z1: OPZIONE | AA1: OPZIONE | AB1: OPZIONE | AC1: OPZIONE | AD1: OPZIONE | AE1: OPZIONE | AF1: OPZIONE | AG1: OPZIONE | AH1: OPZIONE | AI1: OPZIONE | AJ1: OPZIONE | AK1: OPZIONE | AL1: OPZIONE | AM1: OPZIONE | AN1: OPZIONE | AO1: OPZIONE | AP1: OPZIONE | AQ1: OPZIONE | AR1: OPZIONE | AS1: OPZIONE | AT1: OPZIONE | AU1: OPZIONE | AV1: OPZIONE | AW1: OPZIONE | AX1: OPZIONE | AY1: OPZIONE | AZ1: OPZIONE | BA1: OPZIONE | BC1: OPZIONE | BD1: OPZIONE | BE1: OPZIONE | BF1: OPZIONE | BH1: OPZIONE | BI1: OPZIONE
A2: ID | B2: PRODUZIONE | C2: PRESSA | D2: GRUPPO DI TAGLIO | E2: TRABATTO | F2: ELEVATORE | G2: ESSICCATOIO | H2: RAFFREDDATORE | J2: Ore Studio Elettromeccanico | K2: Ore Studio Software PLC | L2: Ore Studio Software HMI | M2: Ore Costruzione Quadro | N2: Ore Collaudo Interno Elettromeccanico | O2: Ore Collaudo Interno Software | P2: Totale Costo Manodopera per Studio e Costruzione QE (Materiale STANDARD Normative CE) | Q2: Totale Costo Manodopera per Studio e Costruzione QE (Materiale Fuori STANDARD e/o Normative UL/EN) | R2: Totale Costo Materiali QE (Materiale STANDARD Normative CE) | S2: Totale Costo Materiali QE(Materiale Fuori STANDARD e/o Normative UL/EN) | T2: Dimensioni - Struttura QE (Materiale Standard Normativa CE) | U2: Totale Costo QE (Materiale STANDARD Normative CE) | V2: Totale Costo QE(Materiale Fuori STANDARD e/o Normative UL/EN) | X2: Alimentaizone Speciale (380/440V 60Hz) | Y2: Alimentaizone Speciale (220V 50/60Hz) | Z2: QE Climatizzati - Climatizzatori da tetto | AA2: QE Climatizzati - Climatizzatori da parete | AB2: Box Climatizzato per Sistema di Supervisione | AC2: 2° Stazione di supervisione | AD2: Gestione Dosaggio Semola Gravimetrico (Acquisizione Celle + Hw + Sw) | AE2: Gestione Additivi - 1 Componente Liquido - Pompa Peristaltica + Tank con Miscelatore - Integrazione in QE + QE Preparazione | AF2: Gestione Additivi - 1 Componente Secco - Microdosatore Volumetrico Storci- Integrazione in QE | AG2: Gestione Additivi - 1 Componente Secco - Microdosatore Gravimetrico Storci - Integrazione in QE | AH2: Gestione Additivi - 1 Componente Secco/Liquido - Interfacciamento con QE Dosaggio Esterno (General Dosing - Schenck - Ecc) | AI2: Estrusori con Motori a Riluttanza | AJ2: Raffreddamento Olio Riduttori Viti di estrusione | AK2: Interfacciamento con Tranciapiegatrici | AL2: Motorizzazione singola piani | AM2: Motorizzaziooni a doppia polarità per comando piani | AN2: Gruppo ByPass Idraulico con doppia valvola | AO2: Espulsione Aria Trabatto comandata con Inverter | AP2: Lama D'Aria Ingresso Trabatto | AQ2: Ventilazione Riscaldata Sotto Trafila | AR2: Ventilazioni comandate con Inverter | AS2: TELECAMERE Ambientali (4 Telecamere) | AT2: Interfacciamento con Tranciapiegatrici | AU2: Optional | AV2: Optional | AW2: Optional | AX2: Optional | AY2: Optional | AZ2: Optional | BA2: Optional | BC2: IoT - Sistema Predittivo Manutenzione - Motoriduttori e Reggispinta Estrusori (LIVELLO 01) | BD2: IoT - Sistema Predittivo Manutenzione - Ventilazioni Essiccatoio (6 Ventilatori) (LIVELLO 01) | BE2: IoT - Sistema Predittivo Qualità - Colore Prodotto (LIVELLO 01) | BF2: IoT - Sistema Predittivo Qualità - Umidità Prodotto (IMKO+BUCHI) (LIVELLO 01) | BH2: IoT - Sistema Predittivo LIVELLO 02 - Pacchetto Base e Configurazione Infrastruttura IoT (Nessuna Licenze) | BI2: IoT - Sistema Predittivo LIVELLO 02 - Canone Annuale Licenze IoT (1 Anno obbligatorio)
X3: 1 | Y3: 2 | Z3: 3 | AA3: 4 | AB3: 5 | AC3: 6 | AD3: 7 | AE3: 8 | AF3: 9 | AG3: 10 | AH3: 11 | AI3: 12 | AJ3: 13 | AK3: 14 | AL3: 15 | AM3: 16 | AN3: 17 | AO3: 18 | AP3: 19 | AQ3: 20 | AR3: 21 | AS3: 22 | AT3: 23 | AU3: 24 | AV3: 25 | AW3: 26 | AX3: 27 | AY3: 28 | AZ3: 29 | BA3: 30
A4: 1 | B4: 500 | C4: --- | D4: --- | E4: --- | G4: --- | H4: --- | J4: 0 | K4: 0 | L4: 0 | M4: 0 | N4: 0 | O4: 0 | P4: =(VALORI!B$3 * 'PASTA CORTA - ECOSYSTEM'!J4) + (VALORI!B$4 * 'PASTA CORTA - ECOSYSTEM'!K4) + (VALORI!B$4 * 'PASTA CORTA - ECOSYSTEM'!L4) + (VALORI!B$5 * 'PASTA CORTA - ECOSYSTEM'!M4) + (VALORI!B$6 * 'PASTA CORTA - ECOSYSTEM'!N4) + (VALORI!B$7 * 'PASTA CORTA - ECOSYSTEM'!O4) -> 0 | Q4: =(P4*25%)+P4 -> 0 | R4: 0 | S4: =(R4*20%)+R4 -> 0 | U4: =P4+R4 -> 0 | V4: =Q4+S4 -> 0 | W4: + | X4: =(R4*8%) -> 0 | Y4: =(R4*20%) -> 0 | Z4: 0 | AA4: =(Z4*65%)+Z4 -> 0 | AB4: 0 | AC4: 0 | AD4: 0 | AE4: 0 | AF4: 0 | AG4: 0 | AH4: 0 | AI4: 0 | AJ4: 0 | AK4: 0 | AL4: 0 | AM4: =(AL4*15%) -> 0 | AN4: 0 | AO4: 0 | AP4: 0 | AQ4: 0 | AR4: DaSDef | AS4: 0 | AT4: 0 | AU4: 0 | AV4: 0 | AW4: 0 | AX4: 0 | AY4: 0 | AZ4: 0 | BA4: 0
A5: 2 | B5: 750 | C5: FA.ST. 160.1-400 TV | D5: LANDUCCI/NICCOLAI | E5: TMU/8,5/ATR | F5: Z 400 STD | G5: TCM-ECOSYSTEM 7,1/9 | H5: R.M.N. 2/1 | J5: 80 | K5: 40 | L5: 40 | M5: 350 | N5: 30 | O5: 80 | P5: =(VALORI!B$3 * 'PASTA CORTA - ECOSYSTEM'!J5) + (VALORI!B$4 * 'PASTA CORTA - ECOSYSTEM'!K5) + (VALORI!B$4 * 'PASTA CORTA - ECOSYSTEM'!L5) + (VALORI!B$5 * 'PASTA CORTA - ECOSYSTEM'!M5) + (VALORI!B$6 * 'PASTA CORTA - ECOSYSTEM'!N5) + (VALORI!B$7 * 'PASTA CORTA - ECOSYSTEM'!O5) -> 20060 | Q5: =(P5*25%)+P5 -> 25075 | R5: 61777.732 | S5: =(R5*20%)+R5 -> 74133.278 | T5: A=4800 + B=2800 | U5: =P5+R5 -> 81837.732 | V5: =Q5+S5 -> 99208.278 | W5: + | X5: =(R5*8%) -> 4942.2186 | Y5: =(R5*20%) -> 12355.546 | Z5: 6000 | AA5: =(Z5*65%)+Z5 -> 9900 | AB5: 3800 | AC5: 5500 | AD5: 1300 | AE5: 8000 | AF5: 2200 | AG5: 2800 | AH5: 1500 | AI5: 800 | AJ5: 2100 | AK5: 1600 | AL5: 5000 | AM5: =(AL5*15%) -> 750 | AN5: 720 | AO5: 1700 | AP5: 1700 | AQ5: 1100 | AR5: DaDef | AS5: 8000 | AT5: 1600 | AU5: 0 | AV5: 0 | AW5: 0 | AX5: 0 | AY5: 0 | AZ5: 0 | BA5: 0 | BC5: 400 | BD5: 4800 | BE5: 1100 | BF5: 2880 | BH5: 36650 | BI5: 29290
A6: 3 | B6: 1000 | C6: FA.ST. 160.1-460 TV | D6: LANDUCCI/NICCOLAI | E6: TMU/11/ATR | F6: Z 400 STD | G6: TCM-ECOSYSTEM 9,6/9 | H6: RMN-F 2/1-1 | J6: 90 | K6: 40 | L6: 40 | M6: 370 | N6: 35 | O6: 80 | P6: =(VALORI!B$3 * 'PASTA CORTA - ECOSYSTEM'!J6) + (VALORI!B$4 * 'PASTA CORTA - ECOSYSTEM'!K6) + (VALORI!B$4 * 'PASTA CORTA - ECOSYSTEM'!L6) + (VALORI!B$5 * 'PASTA CORTA - ECOSYSTEM'!M6) + (VALORI!B$6 * 'PASTA CORTA - ECOSYSTEM'!N6) + (VALORI!B$7 * 'PASTA CORTA - ECOSYSTEM'!O6) -> 21155 | Q6: =(P6*25%)+P6 -> 26443.75 | R6: 65573.508 | S6: =(R6*20%)+R6 -> 78688.21 | T6: A=4800 + B=2800 | U6: =P6+R6 -> 86728.508 | V6: =Q6+S6 -> 105131.96 | W6: + | X6: =(R6*8%) -> 5245.8806 | Y6: =(R6*20%) -> 13114.702 | Z6: 6000 | AA6: =(Z6*65%)+Z6 -> 9900 | AB6: 3800 | AC6: 5500 | AD6: 1300 | AE6: 8000 | AF6: 2200 | AG6: 2800 | AH6: 1500 | AI6: 2000 | AJ6: 2100 | AK6: 1600 | AL6: 5000 | AM6: =(AL6*15%) -> 750 | AN6: 720 | AO6: 1700 | AP6: 1700 | AQ6: 1100 | AR6: DaDef | AS6: 8000 | AT6: 1600 | AU6: 0 | AV6: 0 | AW6: 0 | AX6: 0 | AY6: 0 | AZ6: 0 | BA6: 0 | BC6: 400 | BD6: 4800 | BE6: 1100 | BF6: 2880 | BH6: 36650 | BI6: 29290
A7: 4 | B7: 1500 | C7: FA.ST. 200.1-520 TV | D7: LANDUCCI/NICCOLAI | E7: TMU/13/ATR | F7: Z 400 STD | G7: TCM-ECOSYSTEM 10,9/11 | H7: RMN-F 3/1-1 | J7: 90 | K7: 40 | L7: 40 | M7: 400 | N7: 40 | O7: 80 | P7: =(VALORI!B$3 * 'PASTA CORTA - ECOSYSTEM'!J7) + (VALORI!B$4 * 'PASTA CORTA - ECOSYSTEM'!K7) + (VALORI!B$4 * 'PASTA CORTA - ECOSYSTEM'!L7) + (VALORI!B$5 * 'PASTA CORTA - ECOSYSTEM'!M7) + (VALORI!B$6 * 'PASTA CORTA - ECOSYSTEM'!N7) + (VALORI!B$7 * 'PASTA CORTA - ECOSYSTEM'!O7) -> 22170 | Q7: =(P7*25%)+P7 -> 27712.5 | R7: 68047.98 | S7: =(R7*20%)+R7 -> 81657.576 | T7: A=4800 + B=3200 | U7: =P7+R7 -> 90217.98 | V7: =Q7+S7 -> 109370.08 | W7: + | X7: =(R7*8%) -> 5443.8384 | Y7: =(R7*20%) -> 13609.596 | Z7: 7000 | AA7: =(Z7*65%)+Z7 -> 11550 | AB7: 3800 | AC7: 5500 | AD7: 1300 | AE7: 8000 | AF7: 2200 | AG7: 2800 | AH7: 1500 | AI7: 2000 | AJ7: 2100 | AK7: 1600 | AL7: 7000 | AM7: =(AL7*15%) -> 1050 | AN7: 720 | AO7: 1700 | AP7: 1700 | AQ7: 1100 | AR7: DaDef | AS7: 8000 | AT7: 1600 | AU7: 0 | AV7: 0 | AW7: 0 | AX7: 0 | AY7: 0 | AZ7: 0 | BA7: 0 | BC7: 400 | BD7: 4800 | BE7: 1100 | BF7: 2880 | BH7: 36650 | BI7: 29290
A8: 5 | B8: 2000 | C8: FA.ST. 210.1-600 TV | D8: LANDUCCI/NICCOLAI | E8: TMU/15/ATR | F8: Z 600 STD | G8: TCM-ECOSYSTEM 14,6/11 | H8: RMN-F 3/1-1 | J8: 90 | K8: 40 | L8: 40 | M8: 435 | N8: 40 | O8: 80 | P8: =(VALORI!B$3 * 'PASTA CORTA - ECOSYSTEM'!J8) + (VALORI!B$4 * 'PASTA CORTA - ECOSYSTEM'!K8) + (VALORI!B$4 * 'PASTA CORTA - ECOSYSTEM'!L8) + (VALORI!B$5 * 'PASTA CORTA - ECOSYSTEM'!M8) + (VALORI!B$6 * 'PASTA CORTA - ECOSYSTEM'!N8) + (VALORI!B$7 * 'PASTA CORTA - ECOSYSTEM'!O8) -> 23185 | Q8: =(P8*25%)+P8 -> 28981.25 | R8: 69285.216 | S8: =(R8*20%)+R8 -> 83142.259 | T8: A=4800 + B=3600 | U8: =P8+R8 -> 92470.216 | V8: =Q8+S8 -> 112123.51 | W8: + | X8: =(R8*8%) -> 5542.8173 | Y8: =(R8*20%) -> 13857.043 | Z8: 7000 | AA8: =(Z8*65%)+Z8 -> 11550 | AB8: 3800 | AC8: 5500 | AD8: 1300 | AE8: 8000 | AF8: 2200 | AG8: 2800 | AH8: 1500 | AI8: 4000 | AJ8: 2100 | AK8: 1600 | AL8: 7000 | AM8: =(AL8*15%) -> 1050 | AN8: 720 | AO8: 1700 | AP8: 1700 | AQ8: 1100 | AR8: DaDef | AS8: 8000 | AT8: 1600 | AU8: 0 | AV8: 0 | AW8: 0 | AX8: 0 | AY8: 0 | AZ8: 0 | BA8: 0 | BC8: 400 | BD8: 4800 | BE8: 1100 | BF8: 2880 | BH8: 36650 | BI8: 29290
A9: 6 | B9: 2000 | C9: FA.ST. 160.2-460 TV | D9: LANDUCCI/NICCOLAI | E9: TMU/11/ATR | F9: Z 600 STD | G9: TCM-ECOSYSTEM 14,6/11 | H9: RMN-F 3/1-1 | J9: 100 | K9: 45 | L9: 45 | M9: 480 | N9: 45 | O9: 80 | P9: =(VALORI!B$3 * 'PASTA CORTA - ECOSYSTEM'!J9) + (VALORI!B$4 * 'PASTA CORTA - ECOSYSTEM'!K9) + (VALORI!B$4 * 'PASTA CORTA - ECOSYSTEM'!L9) + (VALORI!B$5 * 'PASTA CORTA - ECOSYSTEM'!M9) + (VALORI!B$6 * 'PASTA CORTA - ECOSYSTEM'!N9) + (VALORI!B$7 * 'PASTA CORTA - ECOSYSTEM'!O9) -> 25385 | Q9: =(P9*25%)+P9 -> 31731.25 | R9: 76285.216 | S9: =(R9*20%)+R9 -> 91542.259 | T9: A=4800 + B=3600 | U9: =P9+R9 -> 101670.22 | V9: =Q9+S9 -> 123273.51 | W9: + | X9: =(R9*8%) -> 6102.8173 | Y9: =(R9*20%) -> 15257.043 | Z9: 7000 | AA9: =(Z9*65%)+Z9 -> 11550 | AB9: 3800 | AC9: 5500 | AD9: 1300 | AE9: 8000 | AF9: 2200 | AG9: 2800 | AH9: 1500 | AI9: 4000 | AJ9: 2100 | AK9: 1600 | AL9: 7000 | AM9: 1050 | AN9: 720 | AO9: 1700 | AP9: 1700 | AQ9: 2200 | AR9: DaDef | AS9: 8000 | AT9: 1600 | AU9: 0 | AV9: 0 | AW9: 0 | AX9: 0 | AY9: 0 | AZ9: 0 | BA9: 0 | BC9: 400 | BD9: 4800 | BE9: 1100 | BF9: 2880 | BH9: 36650 | BI9: 29290
A10: 7 | B10: 2500 | C10: FA.ST. 225.1-670 TV | D10: LANDUCCI/NICCOLAI | E10: TMU/19/ATR | F10: Z 600 STD | G10: TCM-ECOSYSTEM 17,1/11 | H10: RMN-F 4/1-1 | J10: 100 | K10: 40 | L10: 40 | M10: 460 | N10: 45 | O10: 80 | P10: =(VALORI!B$3 * 'PASTA CORTA - ECOSYSTEM'!J10) + (VALORI!B$4 * 'PASTA CORTA - ECOSYSTEM'!K10) + (VALORI!B$4 * 'PASTA CORTA - ECOSYSTEM'!L10) + (VALORI!B$5 * 'PASTA CORTA - ECOSYSTEM'!M10) + (VALORI!B$6 * 'PASTA CORTA - ECOSYSTEM'!N10) + (VALORI!B$7 * 'PASTA CORTA - ECOSYSTEM'!O10) -> 24425 | Q10: =(P10*25%)+P10 -> 30531.25 | R10: 71759.688 | S10: =(R10*20%)+R10 -> 86111.626 | T10: A=4800 + B=4000 | U10: =P10+R10 -> 96184.688 | V10: =Q10+S10 -> 116642.88 | W10: + | X10: =(R10*8%) -> 5740.775 | Y10: =(R10*20%) -> 14351.938 | Z10: 8000 | AA10: =(Z10*65%)+Z10 -> 13200 | AB10: 3800 | AC10: 5500 | AD10: 1300 | AE10: 8000 | AF10: 2200 | AG10: 2800 | AH10: 1500 | AI10: 4000 | AJ10: 2100 | AK10: 1600 | AL10: 7000 | AM10: =(AL10*15%) -> 1050 | AN10: 720 | AO10: 1900 | AP10: 1900 | AQ10: 1100 | AR10: DaDef | AS10: 8000 | AT10: 1600 | AU10: 0 | AV10: 0 | AW10: 0 | AX10: 0 | AY10: 0 | AZ10: 0 | BA10: 0 | BC10: 400 | BD10: 4800 | BE10: 1100 | BF10: 2880 | BH10: 36650 | BI10: 29290
A11: 8 | B11: 3000 | C11: FA.ST. 245.1-670 TV 2I | D11: LANDUCCI/NICCOLAI | E11: TMU/19/ATR | F11: Z 600 STD | G11: TCM-L-ECOSYSTEM 14,6/13 | H11: RMN-F 4/1-1 | J11: 100 | K11: 40 | L11: 40 | M11: 480 | N11: 45 | O11: 80 | P11: =(VALORI!B$3 * 'PASTA CORTA - ECOSYSTEM'!J11) + (VALORI!B$4 * 'PASTA CORTA - ECOSYSTEM'!K11) + (VALORI!B$4 * 'PASTA CORTA - ECOSYSTEM'!L11) + (VALORI!B$5 * 'PASTA CORTA - ECOSYSTEM'!M11) + (VALORI!B$6 * 'PASTA CORTA - ECOSYSTEM'!N11) + (VALORI!B$7 * 'PASTA CORTA - ECOSYSTEM'!O11) -> 25005 | Q11: =(P11*25%)+P11 -> 31256.25 | R11: 74234.16 | S11: =(R11*20%)+R11 -> 89080.992 | T11: A=4800 + B=4400 | U11: =P11+R11 -> 99239.16 | V11: =Q11+S11 -> 120337.24 | W11: + | X11: =(R11*8%) -> 5938.7328 | Y11: =(R11*20%) -> 14846.832 | Z11: 8000 | AA11: =(Z11*65%)+Z11 -> 13200 | AB11: 3800 | AC11: 5500 | AD11: 1300 | AE11: 8000 | AF11: 2200 | AG11: 2800 | AH11: 1500 | AI11: 5000 | AJ11: 2100 | AK11: 1600 | AL11: 9000 | AM11: =(AL11*15%) -> 1350 | AN11: 720 | AO11: 1900 | AP11: 1900 | AQ11: 1100 | AR11: DaDef | AS11: 8000 | AT11: 1600 | AU11: 0 | AV11: 0 | AW11: 0 | AX11: 0 | AY11: 0 | AZ11: 0 | BA11: 0 | BC11: 400 | BD11: 4800 | BE11: 1100 | BF11: 2880 | BH11: 36650 | BI11: 29290
A12: 9 | B12: 3500 | C12: --- | D12: --- | E12: --- | F12: --- | G12: --- | H12: --- | J12: 0 | K12: 0 | L12: 0 | M12: 0 | N12: 0 | O12: 0 | P12: =(VALORI!B$3 * 'PASTA CORTA - ECOSYSTEM'!J12) + (VALORI!B$4 * 'PASTA CORTA - ECOSYSTEM'!K12) + (VALORI!B$4 * 'PASTA CORTA - ECOSYSTEM'!L12) + (VALORI!B$5 * 'PASTA CORTA - ECOSYSTEM'!M12) + (VALORI!B$6 * 'PASTA CORTA - ECOSYSTEM'!N12) + (VALORI!B$7 * 'PASTA CORTA - ECOSYSTEM'!O12) -> 0 | Q12: =(P12*25%)+P12 -> 0 | R12: 0 | S12: =(R12*20%)+R12 -> 0 | U12: =P12+R12 -> 0 | V12: =Q12+S12 -> 0 | W12: + | X12: =(R12*8%) -> 0 | Y12: =(R12*20%) -> 0 | Z12: 0 | AA12: =(Z12*65%)+Z12 -> 0 | AB12: 0 | AC12: 0 | AD12: 0 | AE12: 0 | AF12: 0 | AG12: 0 | AH12: 0 | AI12: 0 | AJ12: 0 | AK12: 0 | AL12: 0 | AM12: =(AL12*15%) -> 0 | AN12: 0 | AO12: 0 | AP12: 0 | AQ12: 0 | AR12: DaSDef | AS12: 0 | AT12: 0 | AU12: 0 | AV12: 0 | AW12: 0 | AX12: 0 | AY12: 0 | AZ12: 0 | BA12: 0
A13: 10 | B13: 4000 | C13: FA.ST. 210.2-600 TV | D13: LANDUCCI/NICCOLAI | E13: TMU/26,5/ATR | F13: Z 800 GP STD | G13: TCM-L-ECOSYSTEM 18,4/13 | H13: RMNL-F 4/1-1 | J13: 110 | K13: 50 | L13: 50 | M13: 520 | N13: 50 | O13: 100 | P13: =(VALORI!B$3 * 'PASTA CORTA - ECOSYSTEM'!J13) + (VALORI!B$4 * 'PASTA CORTA - ECOSYSTEM'!K13) + (VALORI!B$4 * 'PASTA CORTA - ECOSYSTEM'!L13) + (VALORI!B$5 * 'PASTA CORTA - ECOSYSTEM'!M13) + (VALORI!B$6 * 'PASTA CORTA - ECOSYSTEM'!N13) + (VALORI!B$7 * 'PASTA CORTA - ECOSYSTEM'!O13) -> 28200 | Q13: =(P13*25%)+P13 -> 35250 | R13: 90318.228 | S13: =(R13*20%)+R13 -> 108381.87 | T13: A=5200 + B=4400 | U13: =P13+R13 -> 118518.23 | V13: =Q13+S13 -> 143631.87 | W13: + | X13: =(R13*8%) -> 7225.4582 | Y13: =(R13*20%) -> 18063.646 | Z13: 10000 | AA13: =(Z13*65%)+Z13 -> 16500 | AB13: 3800 | AC13: 5500 | AD13: 1300 | AE13: 8000 | AF13: 2200 | AG13: 2800 | AH13: 1500 | AI13: 4000 | AJ13: 4200 | AK13: 2200 | AL13: 9000 | AM13: =(AL13*15%) -> 1350 | AN13: 720 | AO13: 1900 | AP13: 1900 | AQ13: 2200 | AR13: DaDef | AS13: 8000 | AT13: 2200 | AU13: 0 | AV13: 0 | AW13: 0 | AX13: 0 | AY13: 0 | AZ13: 0 | BA13: 0 | BC13: 800 | BD13: 4800 | BE13: 1100 | BF13: 2880 | BH13: 36650 | BI13: 29290
A14: 11 | B14: 4500 | C14: FA.ST. 210.2-600 TV | D14: LANDUCCI/NICCOLAI | E14: TMU/26,5/ATR | F14: Z 800 GP STD | G14: TCM-L-ECOSYSTEM 20,9/13 | H14: RMNL-F 5/1-1 | J14: 110 | K14: 50 | L14: 50 | M14: 530 | N14: 50 | O14: 100 | P14: =(VALORI!B$3 * 'PASTA CORTA - ECOSYSTEM'!J14) + (VALORI!B$4 * 'PASTA CORTA - ECOSYSTEM'!K14) + (VALORI!B$4 * 'PASTA CORTA - ECOSYSTEM'!L14) + (VALORI!B$5 * 'PASTA CORTA - ECOSYSTEM'!M14) + (VALORI!B$6 * 'PASTA CORTA - ECOSYSTEM'!N14) + (VALORI!B$7 * 'PASTA CORTA - ECOSYSTEM'!O14) -> 28490 | Q14: =(P14*25%)+P14 -> 35612.5 | R14: 92792.7 | S14: =(R14*20%)+R14 -> 111351.24 | T14: A=5200 + B=4800 | U14: =P14+R14 -> 121282.7 | V14: =Q14+S14 -> 146963.74 | W14: + | X14: =(R14*8%) -> 7423.416 | Y14: =(R14*20%) -> 18558.54 | Z14: 11000 | AA14: =(Z14*65%)+Z14 -> 18150 | AB14: 3800 | AC14: 5500 | AD14: 1300 | AE14: 8000 | AF14: 2200 | AG14: 2800 | AH14: 1500 | AI14: 4000 | AJ14: 4200 | AK14: 2200 | AL14: 9000 | AM14: =(AL14*15%) -> 1350 | AN14: 720 | AO14: 1900 | AP14: 1900 | AQ14: 2200 | AR14: DaDef | AS14: 8000 | AT14: 2200 | AU14: 0 | AV14: 0 | AW14: 0 | AX14: 0 | AY14: 0 | AZ14: 0 | BA14: 0 | BC14: 800 | BD14: 4800 | BE14: 1100 | BF14: 2880 | BH14: 36650 | BI14: 29290
A15: 12 | B15: 5000 | C15: FA.ST. 225.2-670 TV | D15: LANDUCCI/NICCOLAI | E15: TMD/19/VS | F15: Z 800 GP STD | G15: TCM-L-ECOSYSTEM 23,4/13 | H15: RMNL-F 5/1-1 | J15: 110 | K15: 50 | L15: 50 | M15: 550 | N15: 50 | O15: 100 | P15: =(VALORI!B$3 * 'PASTA CORTA - ECOSYSTEM'!J15) + (VALORI!B$4 * 'PASTA CORTA - ECOSYSTEM'!K15) + (VALORI!B$4 * 'PASTA CORTA - ECOSYSTEM'!L15) + (VALORI!B$5 * 'PASTA CORTA - ECOSYSTEM'!M15) + (VALORI!B$6 * 'PASTA CORTA - ECOSYSTEM'!N15) + (VALORI!B$7 * 'PASTA CORTA - ECOSYSTEM'!O15) -> 29070 | Q15: =(P15*25%)+P15 -> 36337.5 | R15: 100216.12 | S15: =(R15*20%)+R15 -> 120259.34 | T15: A=5200 + B=5200 | U15: =P15+R15 -> 129286.12 | V15: =Q15+S15 -> 156596.84 | W15: + | X15: =(R15*8%) -> 8017.2893 | Y15: =(R15*20%) -> 20043.223 | Z15: 12000 | AA15: =(Z15*65%)+Z15 -> 19800 | AB15: 3800 | AC15: 5500 | AD15: 1300 | AE15: 8000 | AF15: 2200 | AG15: 2800 | AH15: 1500 | AI15: 8000 | AJ15: 4200 | AK15: 2200 | AL15: 9000 | AM15: =(AL15*15%) -> 1350 | AN15: 720 | AO15: 3400 | AP15: 3400 | AQ15: 2200 | AR15: DaDef | AS15: 8000 | AT15: 2200 | AU15: 0 | AV15: 0 | AW15: 0 | AX15: 0 | AY15: 0 | AZ15: 0 | BA15: 0 | BC15: 800 | BD15: 4800 | BE15: 1100 | BF15: 2880 | BH15: 36650 | BI15: 29290
A16: 13 | B16: 5500 | C16: --- | D16: --- | E16: --- | F16: --- | G16: --- | H16: --- | J16: 0 | K16: 0 | L16: 0 | M16: 0 | N16: 0 | O16: 0 | P16: =(VALORI!B$3 * 'PASTA CORTA - ECOSYSTEM'!J16) + (VALORI!B$4 * 'PASTA CORTA - ECOSYSTEM'!K16) + (VALORI!B$4 * 'PASTA CORTA - ECOSYSTEM'!L16) + (VALORI!B$5 * 'PASTA CORTA - ECOSYSTEM'!M16) + (VALORI!B$6 * 'PASTA CORTA - ECOSYSTEM'!N16) + (VALORI!B$7 * 'PASTA CORTA - ECOSYSTEM'!O16) -> 0 | Q16: =(P16*25%)+P16 -> 0 | R16: 0 | S16: =(R16*20%)+R16 -> 0 | U16: =P16+R16 -> 0 | V16: =Q16+S16 -> 0 | W16: + | X16: =(R16*8%) -> 0 | Y16: =(R16*20%) -> 0 | Z16: 0 | AA16: =(Z16*65%)+Z16 -> 0 | AB16: 0 | AC16: 0 | AD16: 0 | AE16: 0 | AF16: 0 | AG16: 0 | AH16: 0 | AI16: 0 | AJ16: 0 | AK16: 0 | AL16: 0 | AM16: =(AL16*15%) -> 0 | AN16: 0 | AO16: 0 | AP16: 0 | AQ16: 0 | AR16: DaSDef | AS16: 0 | AT16: 0 | AU16: 0 | AV16: 0 | AW16: 0 | AX16: 0 | AY16: 0 | AZ16: 0 | BA16: 0
A17: 14 | B17: 6000 | C17: FA.ST. 245.2-670 TV | D17: LANDUCCI/NICCOLAI | E17: TMD/19/VS | F17: Z 1100 GP STD | G17: TCM-L-ECOSYSTEM 23,4/15 | H17: RMNL-F 6/1-1 | J17: 110 | K17: 50 | L17: 50 | M17: 620 | N17: 60 | O17: 100 | P17: =(VALORI!B$3 * 'PASTA CORTA - ECOSYSTEM'!J17) + (VALORI!B$4 * 'PASTA CORTA - ECOSYSTEM'!K17) + (VALORI!B$4 * 'PASTA CORTA - ECOSYSTEM'!L17) + (VALORI!B$5 * 'PASTA CORTA - ECOSYSTEM'!M17) + (VALORI!B$6 * 'PASTA CORTA - ECOSYSTEM'!N17) + (VALORI!B$7 * 'PASTA CORTA - ECOSYSTEM'!O17) -> 31390 | Q17: =(P17*25%)+P17 -> 39237.5 | R17: 105165.06 | S17: =(R17*20%)+R17 -> 126198.07 | T17: A=5200 + B=5200 | U17: =P17+R17 -> 136555.06 | V17: =Q17+S17 -> 165435.57 | W17: + | X17: =(R17*8%) -> 8413.2048 | Y17: =(R17*20%) -> 21033.012 | Z17: 12000 | AA17: =(Z17*65%)+Z17 -> 19800 | AB17: 3800 | AC17: 5500 | AD17: 1300 | AE17: 8000 | AF17: 2200 | AG17: 2800 | AH17: 1500 | AI17: 8000 | AJ17: 4200 | AK17: 2200 | AL17: 11000 | AM17: =(AL17*15%) -> 1650 | AN17: 720 | AO17: 3400 | AP17: 3400 | AQ17: 2200 | AR17: DaDef | AS17: 8000 | AT17: 2200 | AU17: 0 | AV17: 0 | AW17: 0 | AX17: 0 | AY17: 0 | AZ17: 0 | BA17: 0 | BC17: 800 | BD17: 4800 | BE17: 1100 | BF17: 2880 | BH17: 36650 | BI17: 29290
A18: 15 | B18: 8000 | C18: --- | D18: --- | E18: --- | G18: --- | H18: --- | J18: 0 | K18: 0 | L18: 0 | M18: 0 | N18: 0 | O18: 0 | P18: =(VALORI!B$3 * 'PASTA CORTA - ECOSYSTEM'!J18) + (VALORI!B$4 * 'PASTA CORTA - ECOSYSTEM'!K18) + (VALORI!B$4 * 'PASTA CORTA - ECOSYSTEM'!L18) + (VALORI!B$5 * 'PASTA CORTA - ECOSYSTEM'!M18) + (VALORI!B$6 * 'PASTA CORTA - ECOSYSTEM'!N18) + (VALORI!B$7 * 'PASTA CORTA - ECOSYSTEM'!O18) -> 0 | Q18: =(P18*25%)+P18 -> 0 | R18: 0 | S18: =(R18*20%)+R18 -> 0 | U18: =P18+R18 -> 0 | V18: =Q18+S18 -> 0 | W18: + | X18: =(R18*8%) -> 0 | Y18: =(R18*20%) -> 0 | Z18: 0 | AA18: =(Z18*65%)+Z18 -> 0 | AB18: 0 | AC18: 0 | AD18: 0 | AE18: 0 | AF18: 0 | AG18: 0 | AH18: 0 | AI18: 0 | AJ18: 0 | AK18: 0 | AL18: 0 | AM18: =(AL18*15%) -> 0 | AN18: 0 | AO18: 0 | AP18: 0 | AQ18: 0 | AR18: DaSDef | AS18: 0 | AT18: 0 | AU18: 0 | AV18: 0 | AW18: 0 | AX18: 0 | AY18: 0 | AZ18: 0 | BA18: 0
A19: 16 | B19: 9000 | C19: FA.ST. 210.4-600 TV | D19: LANDUCCI/NICCOLAI | E19: TMD 26,5 | F19: ND | G19: TCM-L INC. V.V. 15,9/17 + TCM-L ESS. 14,6/15 | H19: RMN_L-F 9/2-1 | J19: 120 | K19: 70 | L19: 60 | M19: 760 | N19: 60 | O19: 120 | P19: =(VALORI!B$3 * 'PASTA CORTA - ECOSYSTEM'!J19) + (VALORI!B$4 * 'PASTA CORTA - ECOSYSTEM'!K19) + (VALORI!B$4 * 'PASTA CORTA - ECOSYSTEM'!L19) + (VALORI!B$5 * 'PASTA CORTA - ECOSYSTEM'!M19) + (VALORI!B$6 * 'PASTA CORTA - ECOSYSTEM'!N19) + (VALORI!B$7 * 'PASTA CORTA - ECOSYSTEM'!O19) -> 37720 | Q19: =(P19*25%)+P19 -> 47150 | R19: 148468.32 | S19: =(R19*20%)+R19 -> 178161.98 | T19: A=5200 + B=5200 + C=5200 | U19: =P19+R19 -> 186188.32 | V19: =Q19+S19 -> 225311.98 | W19: + | X19: =(R19*8%) -> 11877.466 | Y19: =(R19*20%) -> 29693.664 | Z19: 14000 | AA19: =(Z19*65%)+Z19 -> 23100 | AB19: 3800 | AC19: 5500 | AD19: 1300 | AE19: 8000 | AF19: 2200 | AG19: 2800 | AH19: 1500 | AI19: 12000 | AJ19: 8400 | AK19: 3200 | AL19: 13000 | AM19: =(AL19*15%) -> 1950 | AN19: 960 | AO19: 3800 | AP19: 3800 | AQ19: 4400 | AR19: DaDef | AS19: 8000 | AT19: 3200 | AU19: 0 | AV19: 0 | AW19: 0 | AX19: 0 | AY19: 0 | AZ19: 0 | BA19: 0 | BC19: 1600 | BD19: 4800 | BE19: 1100 | BF19: 2880 | BH19: 36650 | BI19: 29290
A20: 17 | B20: 12000 | C20: FA.ST. 245.4-670 | D20: LANDUCCI/NICCOLAI | E20: TMD 36 | F20: ND | G20: TCM-L INC. V.V. 19,6/17 + Z 1600 GP + TCM-L ESS. 18,4/15 | H20: RMN_L-F 12/1-2 | J20: 130 | K20: 100 | L20: 80 | M20: 900 | N20: 100 | O20: 160 | P20: =(VALORI!B$3 * 'PASTA CORTA - ECOSYSTEM'!J20) + (VALORI!B$4 * 'PASTA CORTA - ECOSYSTEM'!K20) + (VALORI!B$4 * 'PASTA CORTA - ECOSYSTEM'!L20) + (VALORI!B$5 * 'PASTA CORTA - ECOSYSTEM'!M20) + (VALORI!B$6 * 'PASTA CORTA - ECOSYSTEM'!N20) + (VALORI!B$7 * 'PASTA CORTA - ECOSYSTEM'!O20) -> 46730 | Q20: =(P20*25%)+P20 -> 58412.5 | R20: 167026.86 | S20: =(R20*20%)+R20 -> 200432.23 | T20: A=5200 + B=5200 + C=5200 + D=4000 | U20: =P20+R20 -> 213756.86 | V20: =Q20+S20 -> 258844.73 | W20: + | X20: =(R20*8%) -> 13362.149 | Y20: =(R20*20%) -> 33405.372 | Z20: 18000 | AA20: =(Z20*65%)+Z20 -> 29700 | AB20: 3800 | AC20: 5500 | AD20: 1300 | AE20: 8000 | AF20: 2200 | AG20: 2800 | AH20: 1500 | AI20: 16000 | AJ20: 8400 | AK20: 3200 | AL20: 15000 | AM20: =(AL20*15%) -> 2250 | AN20: 960 | AO20: 3800 | AP20: 3800 | AQ20: 4400 | AR20: DaDef | AS20: 8000 | AT20: 3200 | AU20: 0 | AV20: 0 | AW20: 0 | AX20: 0 | AY20: 0 | AZ20: 0 | BA20: 0 | BC20: 1600 | BD20: 4800 | BE20: 1100 | BF20: 2880 | BH20: 36650 | BI20: 29290
A21: 18 | B21: 0 | C21: --- | D21: --- | E21: --- | F21: --- | G21: --- | H21: --- | J21: 0 | K21: 0 | L21: 0 | M21: 0 | N21: 0 | O21: 0 | P21: =(VALORI!B$3 * 'PASTA CORTA - ECOSYSTEM'!J21) + (VALORI!B$4 * 'PASTA CORTA - ECOSYSTEM'!K21) + (VALORI!B$4 * 'PASTA CORTA - ECOSYSTEM'!L21) + (VALORI!B$5 * 'PASTA CORTA - ECOSYSTEM'!M21) + (VALORI!B$6 * 'PASTA CORTA - ECOSYSTEM'!N21) + (VALORI!B$7 * 'PASTA CORTA - ECOSYSTEM'!O21) -> 0 | Q21: =(P21*25%)+P21 -> 0 | R21: 0 | S21: =(R21*20%)+R21 -> 0 | U21: =P21+R21 -> 0 | V21: =Q21+S21 -> 0 | W21: + | X21: =(R21*8%) -> 0 | Y21: =(R21*20%) -> 0 | Z21: 0 | AA21: =(Z21*65%)+Z21 -> 0 | AB21: 0 | AC21: 0 | AD21: 0 | AE21: 0 | AF21: 0 | AG21: 0 | AH21: 0 | AI21: 0 | AJ21: 0 | AK21: 0 | AL21: 0 | AM21: =(AL21*15%) -> 0 | AN21: 0 | AO21: 0 | AP21: 0 | AQ21: 0 | AR21: DaSDef | AS21: 0 | AT21: 0 | AU21: 0 | AV21: 0 | AW21: 0 | AX21: 0 | AY21: 0 | AZ21: 0 | BA21: 0
A22: 19 | B22: 0 | C22: --- | D22: --- | E22: --- | F22: --- | G22: --- | H22: --- | J22: 0 | K22: 0 | L22: 0 | M22: 0 | N22: 0 | O22: 0 | P22: =(VALORI!B$3 * 'PASTA CORTA - ECOSYSTEM'!J22) + (VALORI!B$4 * 'PASTA CORTA - ECOSYSTEM'!K22) + (VALORI!B$4 * 'PASTA CORTA - ECOSYSTEM'!L22) + (VALORI!B$5 * 'PASTA CORTA - ECOSYSTEM'!M22) + (VALORI!B$6 * 'PASTA CORTA - ECOSYSTEM'!N22) + (VALORI!B$7 * 'PASTA CORTA - ECOSYSTEM'!O22) -> 0 | Q22: =(P22*25%)+P22 -> 0 | R22: 0 | S22: =(R22*20%)+R22 -> 0 | U22: =P22+R22 -> 0 | V22: =Q22+S22 -> 0 | W22: + | X22: =(R22*8%) -> 0 | Y22: =(R22*20%) -> 0 | Z22: 0 | AA22: =(Z22*65%)+Z22 -> 0 | AB22: 0 | AC22: 0 | AD22: 0 | AE22: 0 | AF22: 0 | AG22: 0 | AH22: 0 | AI22: 0 | AJ22: 0 | AK22: 0 | AL22: 0 | AM22: =(AL22*15%) -> 0 | AN22: 0 | AO22: 0 | AP22: 0 | AQ22: 0 | AR22: DaSDef | AS22: 0 | AT22: 0 | AU22: 0 | AV22: 0 | AW22: 0 | AX22: 0 | AY22: 0 | AZ22: 0 | BA22: 0
T25: Incremento Ore Attività per Optionals | V25: PLC h + | W25: + | X25: 0 | Y25: 0 | Z25: 0 | AA25: 0 | AB25: 0 | AC25: 0 | AD25: 4 | AE25: 8 | AF25: 8 | AG25: 8 | AH25: 8 | AI25: 0 | AJ25: 8 | AK25: 4 | AL25: 30 | AM25: 2 | AN25: 2 | AO25: 1 | AP25: 1 | AQ25: 2 | AS25: 0 | AT25: 4 | AU25: 30 | AV25: 2 | AW25: 2 | AX25: 1 | AY25: 1 | AZ25: 2 | BC25: 8 | BD25: 16 | BE25: 6 | BF25: 6
V26: HMI h+ | W26: + | X26: 0 | Y26: 0 | Z26: 0 | AA26: 0 | AB26: 0 | AC26: 0 | AD26: 8 | AE26: 8 | AF26: 8 | AG26: 8 | AH26: 8 | AI26: 0 | AJ26: 8 | AK26: 4 | AL26: 30 | AM26: 2 | AN26: 2 | AO26: 1 | AP26: 1 | AQ26: 2 | AS26: 0 | AT26: 4 | AU26: 30 | AV26: 2 | AW26: 2 | AX26: 1 | AY26: 1 | AZ26: 2 | BC26: 8 | BD26: 16 | BE26: 6 | BF26: 6
B27: CE | V27: SCH h + | W27: + | X27: 10 | Y27: 30 | Z27: 8 | AA27: 8 | AB27: 8 | AC27: 2 | AD27: 6 | AE27: 8 | AF27: 10 | AG27: 10 | AH27: 10 | AI27: 4 | AJ27: 8 | AK27: 5 | AL27: 20 | AM27: 4 | AN27: 4 | AO27: 2 | AP27: 4 | AQ27: 1 | AS27: 15 | AT27: 5 | AU27: 20 | AV27: 4 | AW27: 4 | AX27: 2 | AY27: 4 | AZ27: 1 | BC27: 8 | BD27: 16 | BE27: 6 | BF27: 6
V28: OFF h + | W28: + | X28: 30 | Y28: 90 | Z28: 24 | AA28: 24 | AB28: 20 | AC28: 1 | AD28: 4 | AE28: 50 | AF28: 10 | AG28: 5 | AH28: 5 | AI28: 0 | AJ28: 24 | AK28: 5 | AL28: 30 | AM28: 8 | AN28: 4 | AO28: 4 | AP28: 12 | AQ28: 8 | AS28: 3 | AT28: 5 | AU28: 30 | AV28: 8 | AW28: 4 | AX28: 4 | AY28: 12 | AZ28: 8 | BC28: 10 | BD28: 50 | BE28: 20 | BF28: 20
A32: CONFIGURATORE QUADRO ELETTRICO - XXXXXX - CLIENTE
A34: ID | B34: PRODUZIONE | C34: DESCRIZIONE | J34: Ore Studio Elettromeccanico | K34: Ore Studio Software PLC | L34: Ore Studio Software HMI | M34: Ore Costruzione Quadro | N34: Ore Collaudo Interno Elettromeccanico | O34: Ore Collaudo Interno Software | P34: Totale Costo Manodopera per Studio e Costruzione QE (Materiale STANDARD Normative CE) | Q34: Totale Costo Manodopera per Studio e Costruzione QE (Materiale Fuori STANDARD e/o Normative UL/EN) | R34: Totale Costo Materiali QE (Materiale STANDARD Normative CE) | S34: Totale Costo Materiali QE(Materiale Fuori STANDARD e/o Normative UL/EN) | T34: Dimensioni - Struttura QE (Materiale Standard Normativa CE) | U34: Totale Costo QE (Materiale STANDARD Normative CE) | V34: Totale Costo QE(Materiale Fuori STANDARD e/o Normative UL/EN)
A36: LINEA
A37: 2 | B37: {=INDEX(B4:B20,$A$37,0)} -> 750 | C37: {=INDEX(C4:C22,$A$37,0)} -> FA.ST. 160.1-400 TV | D37: {=INDEX(D4:D22,$A$37,0)} -> LANDUCCI/NICCOLAI | E37: {=INDEX(E4:E22,$A$37,0)} -> TMU/8,5/ATR | F37: {=INDEX(F4:F22,$A$37,0)} -> Z 400 STD | G37: {=INDEX(G4:G22,$A$37,0)} -> TCM-ECOSYSTEM 7,1/9 | H37: {=INDEX(H4:H22,$A$37,0)} -> R.M.N. 2/1 | I37: {=INDEX(I4:I22,$A$37,0)} -> 0 | J37: {=INDEX(J4:J22,$A$37,0)} -> 80 | ... V37: {=INDEX(V4:V22,$A$37,0)} -> 99208.278 | X37: CALCOLO INCREMENTO ANNUALE COSTI MATERIALI
A39: CARATTERISTICHE
A40: CE | B40: NORME | C40: {=IF($A40>0,INDEX(VALORI!F3:F5, MATCH($A40,VALORI!E3:E5, 0),0)," ")} -> Piano Normativo di riferimento - CE
A43: OPTIONALS
A44: 1 | C44: {=IF($A44 > 0, INDEX($X$2:$AS$2, 0, $A44), " ")} -> Alimentaizone Speciale (380/440V 60Hz) | J44: {=IF($A44 > 0, INDEX($X$25:$AS$28,3, $A44), "")} -> 10 | K44: {=IF($A44 > 0, INDEX($X$25:$AS$28,1, $A44), "")} -> 0 | L44: {=IF($A44 > 0, INDEX($X$25:$AS$28,2, $A44), "")} -> 0 | M44: {=IF($A44 > 0, INDEX($X$25:$AS$28,4, $A44), "")} -> 30 | P44: =IF($A44 > 0,(VALORI!B$3 * 'PASTA CORTA - ECOSYSTEM'!J44) + (VALORI!B$4 * 'PASTA CORTA - ECOSYSTEM'!K44) + (VALORI!B$4 * 'PASTA CORTA - ECOSYSTEM'!L44) + (VALORI!B$5 * 'PASTA CORTA - ECOSYSTEM'!M44) + (VALORI!B$6 * 'PASTA CORTA - ECOSYSTEM'!N44) + (VALORI!B$7 * 'PASTA CORTA - ECOSYSTEM'!O44), "") -> 1240 | Q44: =IF($A44 > 0,(P44*25%)+P44,"") -> 1550 | R44: =IF($A44 > 0,U44-P44,"") -> 3702.2186 | S44: =IF($A44 > 0,(R44*20%)+R44,"") -> 4442.6623 | U44: {=IF($A44 > 0,INDEX($X$4:$AS$20,$A$37, $A44),"")} -> 4942.2186 | V44: =IF($A44 > 0,Q44+S44,"") -> 5992.6623 | X44: 44731 | Y44: 10% dal 20/06 | Z44: 4% dal 2023 | AA44: 3% dal 2024
A45: 2 | C45: {=IF($A45 > 0, INDEX($X$2:$AS$2, 0, $A45), " ")} -> Alimentaizone Speciale (220V 50/60Hz) | J45: {=IF($A45 > 0, INDEX($X$25:$AS$28,3, $A45), "")} -> 30 | K45: {=IF($A45 > 0, INDEX($X$25:$AS$28,1, $A45), "")} -> 0 | L45: {=IF($A45 > 0, INDEX($X$25:$AS$28,2, $A45), "")} -> 0 | M45: {=IF($A45 > 0, INDEX($X$25:$AS$28,4, $A45), "")} -> 90 | P45: =IF($A45 > 0,(VALORI!B$3 * 'PASTA CORTA - ECOSYSTEM'!J45) + (VALORI!B$4 * 'PASTA CORTA - ECOSYSTEM'!K45) + (VALORI!B$4 * 'PASTA CORTA - ECOSYSTEM'!L45) + (VALORI!B$5 * 'PASTA CORTA - ECOSYSTEM'!M45) + (VALORI!B$6 * 'PASTA CORTA - ECOSYSTEM'!N45) + (VALORI!B$7 * 'PASTA CORTA - ECOSYSTEM'!O45), "") -> 3720 | Q45: =IF($A45 > 0,(P45*25%)+P45,"") -> 4650 | R45: =IF($A45 > 0,U45-P45,"") -> 8635.5464 | S45: =IF($A45 > 0,(R45*20%)+R45,"") -> 10362.656 | U45: {=IF($A45 > 0,INDEX($X$4:$AS$20,$A$37, $A45),"")} -> 12355.546 | V45: =IF($A45 > 0,Q45+S45,"") -> 15012.656 | X45: 0 | Y45: =(X45*10%)+X45 -> 0 | Z45: =(Y45*4%)+Y45 -> 0 | AA45: =(Z45*3%)+Z45 -> 0
A46: 3 | C46: {=IF($A46 > 0, INDEX($X$2:$AS$2, 0, $A46), " ")} -> QE Climatizzati - Climatizzatori da tetto | J46: {=IF($A46 > 0, INDEX($X$25:$AS$28,3, $A46), "")} -> 8 | K46: {=IF($A46 > 0, INDEX($X$25:$AS$28,1, $A46), "")} -> 0 | L46: {=IF($A46 > 0, INDEX($X$25:$AS$28,2, $A46), "")} -> 0 | M46: {=IF($A46 > 0, INDEX($X$25:$AS$28,4, $A46), "")} -> 24 | P46: =IF($A46 > 0,(VALORI!B$3 * 'PASTA CORTA - ECOSYSTEM'!J46) + (VALORI!B$4 * 'PASTA CORTA - ECOSYSTEM'!K46) + (VALORI!B$4 * 'PASTA CORTA - ECOSYSTEM'!L46) + (VALORI!B$5 * 'PASTA CORTA - ECOSYSTEM'!M46) + (VALORI!B$6 * 'PASTA CORTA - ECOSYSTEM'!N46) + (VALORI!B$7 * 'PASTA CORTA - ECOSYSTEM'!O46), "") -> 992 | Q46: =IF($A46 > 0,(P46*25%)+P46,"") -> 1240 | R46: =IF($A46 > 0,U46-P46,"") -> 5008 | S46: =IF($A46 > 0,(R46*20%)+R46,"") -> 6009.6 | U46: {=IF($A46 > 0,INDEX($X$4:$AS$20,$A$37, $A46),"")} -> 6000 | V46: =IF($A46 > 0,Q46+S46,"") -> 7249.6
A47: 4 | C47: {=IF($A47 > 0, INDEX($X$2:$AS$2, 0, $A47), " ")} -> QE Climatizzati - Climatizzatori da parete | J47: {=IF($A47 > 0, INDEX($X$25:$AS$28,3, $A47), "")} -> 8 | K47: {=IF($A47 > 0, INDEX($X$25:$AS$28,1, $A47), "")} -> 0 | L47: {=IF($A47 > 0, INDEX($X$25:$AS$28,2, $A47), "")} -> 0 | M47: {=IF($A47 > 0, INDEX($X$25:$AS$28,4, $A47), "")} -> 24 | P47: =IF($A47 > 0,(VALORI!B$3 * 'PASTA CORTA - ECOSYSTEM'!J47) + (VALORI!B$4 * 'PASTA CORTA - ECOSYSTEM'!K47) + (VALORI!B$4 * 'PASTA CORTA - ECOSYSTEM'!L47) + (VALORI!B$5 * 'PASTA CORTA - ECOSYSTEM'!M47) + (VALORI!B$6 * 'PASTA CORTA - ECOSYSTEM'!N47) + (VALORI!B$7 * 'PASTA CORTA - ECOSYSTEM'!O47), "") -> 992 | Q47: =IF($A47 > 0,(P47*25%)+P47,"") -> 1240 | R47: =IF($A47 > 0,U47-P47,"") -> 8908 | S47: =IF($A47 > 0,(R47*20%)+R47,"") -> 10689.6 | U47: {=IF($A47 > 0,INDEX($X$4:$AS$20,$A$37, $A47),"")} -> 9900 | V47: =IF($A47 > 0,Q47+S47,"") -> 11929.6 | X47: 0 | Y47: =(X47*10%)+X47 -> 0 | Z47: =(Y47*4%)+Y47 -> 0 | AA47: =(Z47*3%)+Z47 -> 0
A48: 5 | C48: {=IF($A48 > 0, INDEX($X$2:$AS$2, 0, $A48), " ")} -> Box Climatizzato per Sistema di Supervisione | J48: {=IF($A48 > 0, INDEX($X$25:$AS$28,3, $A48), "")} -> 8 | K48: {=IF($A48 > 0, INDEX($X$25:$AS$28,1, $A48), "")} -> 0 | L48: {=IF($A48 > 0, INDEX($X$25:$AS$28,2, $A48), "")} -> 0 | M48: {=IF($A48 > 0, INDEX($X$25:$AS$28,4, $A48), "")} -> 20 | P48: =IF($A48 > 0,(VALORI!B$3 * 'PASTA CORTA - ECOSYSTEM'!J48) + (VALORI!B$4 * 'PASTA CORTA - ECOSYSTEM'!K48) + (VALORI!B$4 * 'PASTA CORTA - ECOSYSTEM'!L48) + (VALORI!B$5 * 'PASTA CORTA - ECOSYSTEM'!M48) + (VALORI!B$6 * 'PASTA CORTA - ECOSYSTEM'!N48) + (VALORI!B$7 * 'PASTA CORTA - ECOSYSTEM'!O48), "") -> 876 | Q48: =IF($A48 > 0,(P48*25%)+P48,"") -> 1095 | R48: =IF($A48 > 0,U48-P48,"") -> 2924 | S48: =IF($A48 > 0,(R48*20%)+R48,"") -> 3508.8 | U48: {=IF($A48 > 0,INDEX($X$4:$AS$20,$A$37, $A48),"")} -> 3800 | V48: =IF($A48 > 0,Q48+S48,"") -> 4603.8 | X48: 52850 | Y48: =(X48*10%)+X48 -> 58135 | Z48: =(Y48*4%)+Y48 -> 60460.4 | AA48: =(Z48*3%)+Z48 -> 62274.212
A49: 6 | C49: {=IF($A49 > 0, INDEX($X$2:$AS$2, 0, $A49), " ")} -> 2° Stazione di supervisione | J49: {=IF($A49 > 0, INDEX($X$25:$AS$28,3, $A49), "")} -> 2 | K49: {=IF($A49 > 0, INDEX($X$25:$AS$28,1, $A49), "")} -> 0 | L49: {=IF($A49 > 0, INDEX($X$25:$AS$28,2, $A49), "")} -> 0 | M49: {=IF($A49 > 0, INDEX($X$25:$AS$28,4, $A49), "")} -> 1 | P49: =IF($A49 > 0,(VALORI!B$3 * 'PASTA CORTA - ECOSYSTEM'!J49) + (VALORI!B$4 * 'PASTA CORTA - ECOSYSTEM'!K49) + (VALORI!B$4 * 'PASTA CORTA - ECOSYSTEM'!L49) + (VALORI!B$5 * 'PASTA CORTA - ECOSYSTEM'!M49) + (VALORI!B$6 * 'PASTA CORTA - ECOSYSTEM'!N49) + (VALORI!B$7 * 'PASTA CORTA - ECOSYSTEM'!O49), "") -> 103 | Q49: =IF($A49 > 0,(P49*25%)+P49,"") -> 128.75 | R49: =IF($A49 > 0,U49-P49,"") -> 5397 | S49: =IF($A49 > 0,(R49*20%)+R49,"") -> 6476.4 | U49: {=IF($A49 > 0,INDEX($X$4:$AS$20,$A$37, $A49),"")} -> 5500 | V49: =IF($A49 > 0,Q49+S49,"") -> 6605.15 | X49: 55650 | Y49: =(X49*10%)+X49 -> 61215 | Z49: =(Y49*4%)+Y49 -> 63663.6 | AA49: =(Z49*3%)+Z49 -> 65573.508
A50: 6 | C50: {=IF($A50 > 0, INDEX($X$2:$AS$2, 0, $A50), " ")} -> 2° Stazione di supervisione | J50: {=IF($A50 > 0, INDEX($X$25:$AS$28,3, $A50), "")} -> 2 | K50: {=IF($A50 > 0, INDEX($X$25:$AS$28,1, $A50), "")} -> 0 | L50: {=IF($A50 > 0, INDEX($X$25:$AS$28,2, $A50), "")} -> 0 | M50: {=IF($A50 > 0, INDEX($X$25:$AS$28,4, $A50), "")} -> 1 | P50: =IF($A50 > 0,(VALORI!B$3 * 'PASTA CORTA - ECOSYSTEM'!J50) + (VALORI!B$4 * 'PASTA CORTA - ECOSYSTEM'!K50) + (VALORI!B$4 * 'PASTA CORTA - ECOSYSTEM'!L50) + (VALORI!B$5 * 'PASTA CORTA - ECOSYSTEM'!M50) + (VALORI!B$6 * 'PASTA CORTA - ECOSYSTEM'!N50) + (VALORI!B$7 * 'PASTA CORTA - ECOSYSTEM'!O50), "") -> 103 | Q50: =IF($A50 > 0,(P50*25%)+P50,"") -> 128.75 | R50: =IF($A50 > 0,U50-P50,"") -> 5397 | S50: =IF($A50 > 0,(R50*20%)+R50,"") -> 6476.4 | U50: {=IF($A50 > 0,INDEX($X$4:$AS$20,$A$37, $A50),"")} -> 5500 | V50: =IF($A50 > 0,Q50+S50,"") -> 6605.15 | X50: 57750 | Y50: =(X50*10%)+X50 -> 63525 | Z50: =(Y50*4%)+Y50 -> 66066 | AA50: =(Z50*3%)+Z50 -> 68047.98
...

Sheet PASTA CORTA - TCM100
A1: PASTA CORTA - TCM 100 | W1: OPZIONE | X1: OPZIONE | Y1: OPZIONE | Z1: OPZIONE | AA1: OPZIONE | AC1: OPZIONE | AD1: OPZIONE | AE1: OPZIONE | AF1: OPZIONE | AG1: OPZIONE | AH1: OPZIONE | AI1: OPZIONE | AJ1: OPZIONE | AK1: OPZIONE | AL1: OPZIONE | AM1: OPZIONE | AN1: OPZIONE | AO1: OPZIONE | AP1: OPZIONE | AQ1: OPZIONE | AS1: OPZIONE | AT1: OPZIONE | AU1: OPZIONE | AV1: OPZIONE | AX1: OPZIONE | AY1: OPZIONE
A2: PRODUZIONE | B2: PRESSA | C2: GRUPPO DI TAGLIO | D2: TRABATTO | E2: ELEVATORE | F2: ESSICCATOIO | G2: RAFFREDDATORE | I2: Ore Studio Elettromeccanico | J2: Ore Studio Software PLC | K2: Ore Studio Software HMI | L2: Ore Costruzione Quadro | M2: Ore Collaudo Interno Elettromeccanico | N2: Ore Collaudo Interno Software | O2: Totale Costo Manodopera per Studio e Costruzione QE (Materiale STANDARD Normative CE) | P2: Totale Costo Manodopera per Studio e Costruzione QE (Materiale Fuori STANDARD e/o Normative UL/EN) | Q2: Totale Costo Materiali QE (Materiale STANDARD Normative CE) | R2: Totale Costo Materiali QE(Materiale Fuori STANDARD e/o Normative UL/EN) | S2: Dimensioni - Struttura QE (Materiale Standard Normativa CE) | T2: Totale Costo QE (Materiale STANDARD Normative CE) | U2: Totale Costo QE(Materiale Fuori STANDARD e/o Normative UL/EN) | W2: Alimentaizone Speciale (380V 60Hz) | X2: Alimentaizone Speciale (220V 50/60Hz) | Y2: QE Climatizzati - Climatizzatori da tetto | Z2: QE Climatizzati - Climatizzatori da parete | AA2: Box Climatizzato per Sistema di Supervisione | AB2: 2° Stazione di supervisione | AC2: Gestione Dosaggio Semola Gravimetrico (Acquisizione Celle + Hw + Sw) | AD2: Gestione Additivi - 1 Componente Liquido - Pompa Peristaltica + Tank con Miscelatore - Integrazione in QE + QE Preparazione | AE2: Gestione Additivi - 1 Componente Secco - Microdosatore Volumetrico Storci- Integrazione in QE | AF2: Gestione Additivi - 1 Componente Secco - Microdosatore Gravimetrico Storci - Integrazione in QE | AG2: Gestione Additivi - 1 Componente Secco/Liquido - Interfacciamento con QE Dosaggio Esterno (General Dosing - Schenck - Ecc) | AH2: Estrusori con Motori a Riluttanza | AI2: Raffreddamento Olio Riduttori Viti di estrusione | AJ2: Interfacciamento con Tranciapiegatrici | AK2: Motorizzazione singola piani | AL2: Motorizzaziooni a doppia polarità per comando piani | AM2: Gruppo ByPass Idraulico con doppia valvola | AN2: Ventilazione Riscaldata Sotto Trafila | AO2: Lama D'Aria Ingresso Trabatto | AP2: Ventilazioni comandate con Inverter | AQ2: TELECAMERE Ambientali (4 Telecamere) | AS2: IoT - Sistema Predittivo Manutenzione - Motoriduttori e Reggispinta Estrusori (LIVELLO 01) | AT2: IoT - Sistema Predittivo Manutenzione - Ventilazioni Essiccatoio (6 Ventilatori) (LIVELLO 01) | AU2: IoT - Sistema Predittivo Qualità - Colore Prodotto (LIVELLO 01) | AV2: IoT - Sistema Predittivo Qualità - Umidità Prodotto (IMKO+BUCHI) (LIVELLO 01) | AX2: IoT - Sistema Predittivo LIVELLO 02 - Pacchetto Base e Configurazione Infrastruttura IoT (Nessuna Licenze) | AY2: IoT - Sistema Predittivo LIVELLO 02 - Canone Annuale Licenze IoT (1 Anno obbligatorio)
A3: 500 | B3: --- | C3: --- | D3: --- | F3: --- | G3: --- | I3: 0 | J3: 0 | K3: 0 | L3: 0 | M3: 0 | N3: 0 | O3: =(VALORI!B$3 * 'PASTA CORTA - TCM100'!I3) + (VALORI!B$4 * 'PASTA CORTA - TCM100'!J3) + (VALORI!B$4 * 'PASTA CORTA - TCM100'!K3) + (VALORI!B$5 * 'PASTA CORTA - TCM100'!L3) + (VALORI!B$6 * 'PASTA CORTA - TCM100'!M3) + (VALORI!B$7 * 'PASTA CORTA - TCM100'!N3) -> 0 | P3: =(O3*25%)+O3 -> 0 | Q3: 0 | R3: =(Q3*20%)+Q3 -> 0 | T3: =O3+Q3 -> 0 | U3: =P3+R3 -> 0 | V3: +
A4: 750 | B4: --- | C4: --- | D4: --- | E4: --- | F4: --- | G4: --- | I4: 0 | J4: 0 | K4: 0 | L4: 0 | M4: 0 | N4: 0 | O4: =(VALORI!B$3 * 'PASTA CORTA - TCM100'!I4) + (VALORI!B$4 * 'PASTA CORTA - TCM100'!J4) + (VALORI!B$4 * 'PASTA CORTA - TCM100'!K4) + (VALORI!B$5 * 'PASTA CORTA - TCM100'!L4) + (VALORI!B$6 * 'PASTA CORTA - TCM100'!M4) + (VALORI!B$7 * 'PASTA CORTA - TCM100'!N4) -> 0 | P4: =(O4*25%)+O4 -> 0 | Q4: 0 | R4: =(Q4*20%)+Q4 -> 0 | T4: =O4+Q4 -> 0 | U4: =P4+R4 -> 0 | V4: + | AS4: 400 | AT4: 4800 | AU4: 1100 | AV4: 2880 | AX4: 36650 | AY4: 29290
A5: 1000 | B5: --- | C5: --- | D5: --- | E5: --- | F5: --- | G5: --- | I5: 0 | J5: 0 | K5: 0 | L5: 0 | M5: 0 | N5: 0 | O5: =(VALORI!B$3 * 'PASTA CORTA - TCM100'!I5) + (VALORI!B$4 * 'PASTA CORTA - TCM100'!J5) + (VALORI!B$4 * 'PASTA CORTA - TCM100'!K5) + (VALORI!B$5 * 'PASTA CORTA - TCM100'!L5) + (VALORI!B$6 * 'PASTA CORTA - TCM100'!M5) + (VALORI!B$7 * 'PASTA CORTA - TCM100'!N5) -> 0 | P5: =(O5*25%)+O5 -> 0 | Q5: 0 | R5: =(Q5*20%)+Q5 -> 0 | T5: =O5+Q5 -> 0 | U5: =P5+R5 -> 0 | V5: + | AS5: 400 | AT5: 4800 | AU5: 1100 | AV5: 2880 | AX5: 36650 | AY5: 29290
A6: 1500 | B6: --- | C6: --- | D6: --- | E6: --- | F6: --- | G6: --- | I6: 0 | J6: 0 | K6: 0 | L6: 0 | M6: 0 | N6: 0 | O6: =(VALORI!B$3 * 'PASTA CORTA - TCM100'!I6) + (VALORI!B$4 * 'PASTA CORTA - TCM100'!J6) + (VALORI!B$4 * 'PASTA CORTA - TCM100'!K6) + (VALORI!B$5 * 'PASTA CORTA - TCM100'!L6) + (VALORI!B$6 * 'PASTA CORTA - TCM100'!M6) + (VALORI!B$7 * 'PASTA CORTA - TCM100'!N6) -> 0 | P6: =(O6*25%)+O6 -> 0 | Q6: 0 | R6: =(Q6*20%)+Q6 -> 0 | T6: =O6+Q6 -> 0 | U6: =P6+R6 -> 0 | V6: + | AS6: 400 | AT6: 4800 | AU6: 1100 | AV6: 2880 | AX6: 36650 | AY6: 29290
A7: 2000 | B7: FA.ST. 210.1-600 TV | C7: LANDUCCI/NICCOLAI | D7: TMU 15 | E7: Z 600 STD | F7: TCM-L-100 13,4/7 | G7: RMN 3/1-1 | I7: 90 | J7: 40 | K7: 40 | L7: 435 | M7: 50 | N7: 80 | O7: =(VALORI!B$3 * 'PASTA CORTA - TCM100'!I7) + (VALORI!B$4 * 'PASTA CORTA - TCM100'!J7) + (VALORI!B$4 * 'PASTA CORTA - TCM100'!K7) + (VALORI!B$5 * 'PASTA CORTA - TCM100'!L7) + (VALORI!B$6 * 'PASTA CORTA - TCM100'!M7) + (VALORI!B$7 * 'PASTA CORTA - TCM100'!N7) -> 23475 | P7: =(O7*25%)+O7 -> 29343.75 | Q7: 69285.216 | R7: =(Q7*20%)+Q7 -> 83142.259 | S7: A=4800 + B=3600 | T7: =O7+Q7 -> 92760.216 | U7: =P7+R7 -> 112486.01 | V7: + | W7: =(Q7*6%) -> 4157.113 | X7: =(Q7*20%) -> 13857.043 | Y7: 7000 | Z7: =(Y7*65%)+Y7 -> 11550 | AA7: 3800 | AB7: 5500 | AC7: 1300 | AD7: 8000 | AE7: 2200 | AF7: 2800 | AG7: 1100 | AH7: 4000 | AI7: 2100 | AJ7: 1600 | AK7: 7000 | AL7: =(AK7*15%) -> 1050 | AM7: 720 | AN7: 1100 | AO7: 1700 | AP7: DaDef | AQ7: 8000 | AS7: 400 | AT7: 4800 | AU7: 1100 | AV7: 2880 | AX7: 36650 | AY7: 29290
A8: 2500 | B8: --- | C8: --- | D8: --- | E8: --- | F8: --- | G8: --- | I8: 0 | J8: 0 | K8: 0 | L8: 0 | M8: 0 | N8: 0 | O8: =(VALORI!B$3 * 'PASTA CORTA - TCM100'!I8) + (VALORI!B$4 * 'PASTA CORTA - TCM100'!J8) + (VALORI!B$4 * 'PASTA CORTA - TCM100'!K8) + (VALORI!B$5 * 'PASTA CORTA - TCM100'!L8) + (VALORI!B$6 * 'PASTA CORTA - TCM100'!M8) + (VALORI!B$7 * 'PASTA CORTA - TCM100'!N8) -> 0 | P8: =(O8*25%)+O8 -> 0 | Q8: 0 | R8: =(Q8*20%)+Q8 -> 0 | S8: A=4800 + B=4000 | T8: =O8+Q8 -> 0 | U8: =P8+R8 -> 0 | V8: + | AQ8: 8000 | AS8: 400 | AT8: 4800 | AU8: 1100 | AV8: 2880 | AX8: 36650 | AY8: 29290
A9: 3000 | B9: FA.ST. 245.1-670 TV/ID | C9: LANDUCCI/NICCOLAI | D9: TMU 19 | E9: Z 600 STD | F9: TCM-L-100 14,6/9 | G9: RMN-F 4/1-1 | I9: 100 | J9: 40 | K9: 40 | L9: 480 | M9: 55 | N9: 80 | O9: =(VALORI!B$3 * 'PASTA CORTA - TCM100'!I9) + (VALORI!B$4 * 'PASTA CORTA - TCM100'!J9) + (VALORI!B$4 * 'PASTA CORTA - TCM100'!K9) + (VALORI!B$5 * 'PASTA CORTA - TCM100'!L9) + (VALORI!B$6 * 'PASTA CORTA - TCM100'!M9) + (VALORI!B$7 * 'PASTA CORTA - TCM100'!N9) -> 25295 | P9: =(O9*25%)+O9 -> 31618.75 | Q9: 74234.16 | R9: =(Q9*20%)+Q9 -> 89080.992 | S9: A=4800 + B=4400 | T9: =O9+Q9 -> 99529.16 | U9: =P9+R9 -> 120699.74 | V9: + | W9: =(Q9*6%) -> 4454.0496 | X9: =(Q9*20%) -> 14846.832 | Y9: 8000 | Z9: =(Y9*65%)+Y9 -> 13200 | AA9: 3800 | AB9: 5500 | AC9: 1300 | AD9: 8000 | AE9: 2200 | AF9: 2800 | AG9: 1100 | AH9: 5000 | AI9: 2100 | AJ9: 1600 | AK9: 9000 | AL9: =(AK9*15%) -> 1350 | AM9: 720 | AN9: 1100 | AO9: 1900 | AP9: DaDef | AQ9: 8000 | AS9: 400 | AT9: 4800 | AU9: 1100 | AV9: 2880 | AX9: 36650 | AY9: 29290
A10: 3500 | B10: --- | C10: --- | D10: --- | E10: --- | F10: --- | G10: --- | I10: 0 | J10: 0 | K10: 0 | L10: 0 | M10: 0 | N10: 0 | O10: =(VALORI!B$3 * 'PASTA CORTA - TCM100'!I10) + (VALORI!B$4 * 'PASTA CORTA - TCM100'!J10) + (VALORI!B$4 * 'PASTA CORTA - TCM100'!K10) + (VALORI!B$5 * 'PASTA CORTA - TCM100'!L10) + (VALORI!B$6 * 'PASTA CORTA - TCM100'!M10) + (VALORI!B$7 * 'PASTA CORTA - TCM100'!N10) -> 0 | P10: =(O10*25%)+O10 -> 0 | Q10: 0 | R10: =(Q10*20%)+Q10 -> 0 | T10: =O10+Q10 -> 0 | U10: =P10+R10 -> 0 | V10: +
A11: 4000 | B11: FA.ST. 210.2-600 TV | C11: LANDUCCI/NICCOLAI | D11: TMU 26,5 | E11: Z 800 GP STD | F11: TCM-L-100 15,9/11 | G11: RMN_L-F 4/1-1 | I11: 110 | J11: 50 | K11: 50 | L11: 520 | M11: 60 | N11: 100 | O11: =(VALORI!B$3 * 'PASTA CORTA - TCM100'!I11) + (VALORI!B$4 * 'PASTA CORTA - TCM100'!J11) + (VALORI!B$4 * 'PASTA CORTA - TCM100'!K11) + (VALORI!B$5 * 'PASTA CORTA - TCM100'!L11) + (VALORI!B$6 * 'PASTA CORTA - TCM100'!M11) + (VALORI!B$7 * 'PASTA CORTA - TCM100'!N11) -> 28490 | P11: =(O11*25%)+O11 -> 35612.5 | Q11: 90318.228 | R11: =(Q11*20%)+Q11 -> 108381.87 | S11: A=5200 + B=4400 | T11: =O11+Q11 -> 118808.23 | U11: =P11+R11 -> 143994.37 | V11: + | W11: =(Q11*6%) -> 5419.0937 | X11: =(Q11*20%) -> 18063.646 | Y11: 10000 | Z11: =(Y11*65%)+Y11 -> 16500 | AA11: 3800 | AB11: 5500 | AC11: 1300 | AD11: 8000 | AE11: 2200 | AF11: 2800 | AG11: 1100 | AH11: 4000 | AI11: 4200 | AJ11: 2200 | AK11: 9000 | AL11: =(AK11*15%) -> 1350 | AM11: 720 | AN11: 2200 | AO11: 1900 | AP11: DaDef | AQ11: 8000 | AS11: 800 | AT11: 4800 | AU11: 1100 | AV11: 2880 | AX11: 36650 | AY11: 29290
A12: 4500 | B12: --- | C12: --- | D12: --- | E12: --- | F12: --- | G12: --- | I12: 110 | J12: 50 | K12: 50 | L12: 530 | M12: 60 | N12: 100 | O12: =(VALORI!B$3 * 'PASTA CORTA - TCM100'!I12) + (VALORI!B$4 * 'PASTA CORTA - TCM100'!J12) + (VALORI!B$4 * 'PASTA CORTA - TCM100'!K12) + (VALORI!B$5 * 'PASTA CORTA - TCM100'!L12) + (VALORI!B$6 * 'PASTA CORTA - TCM100'!M12) + (VALORI!B$7 * 'PASTA CORTA - TCM100'!N12) -> 28780 | P12: =(O12*25%)+O12 -> 35975 | Q12: 92792.7 | R12: =(Q12*20%)+Q12 -> 111351.24 | S12: A=5200 + B=4800 | T12: =O12+Q12 -> 121572.7 | U12: =P12+R12 -> 147326.24 | V12: + | W12: =(Q12*6%) -> 5567.562 | X12: =(Q12*20%) -> 18558.54 | Y12: 11000 | Z12: =(Y12*65%)+Y12 -> 18150 | AA12: 3800 | AB12: 5500 | AC12: 1300 | AD12: 8000 | AE12: 2200 | AF12: 2800 | AG12: 1100 | AH12: 4000 | AI12: 4200 | AJ12: 2200 | AK12: 9000 | AL12: =(AK12*15%) -> 1350 | AM12: 720 | AN12: 2200 | AO12: 1900 | AP12: DaDef | AQ12: 8000 | AS12: 800 | AT12: 4800 | AU12: 1100 | AV12: 2880 | AX12: 36650 | AY12: 29290
A13: 5000 | B13: FA.ST. 225.2-670 TV | C13: LANDUCCI/NICCOLAI | D13: TMD 19 | E13: Z 800 GP STD | F13: TCM-L-100 19,6/11 | G13: RMN_L-F 5/1-1 | I13: 110 | J13: 50 | K13: 50 | L13: 550 | M13: 65 | N13: 100 | O13: =(VALORI!B$3 * 'PASTA CORTA - TCM100'!I13) + (VALORI!B$4 * 'PASTA CORTA - TCM100'!J13) + (VALORI!B$4 * 'PASTA CORTA - TCM100'!K13) + (VALORI!B$5 * 'PASTA CORTA - TCM100'!L13) + (VALORI!B$6 * 'PASTA CORTA - TCM100'!M13) + (VALORI!B$7 * 'PASTA CORTA - TCM100'!N13) -> 29505 | P13: =(O13*25%)+O13 -> 36881.25 | Q13: 100216.12 | R13: =(Q13*20%)+Q13 -> 120259.34 | S13: A=5200 + B=5200 | T13: =O13+Q13 -> 129721.12 | U13: =P13+R13 -> 157140.59 | V13: + | W13: =(Q13*6%) -> 6012.967 | X13: =(Q13*20%) -> 20043.223 | Y13: 12000 | Z13: =(Y13*65%)+Y13 -> 19800 | AA13: 3800 | AB13: 5500 | AC13: 1300 | AD13: 8000 | AE13: 2200 | AF13: 2800 | AG13: 1100 | AH13: 8000 | AI13: 4200 | AJ13: 2200 | AK13: 9000 | AL13: =(AK13*15%) -> 1350 | AM13: 720 | AN13: 2200 | AO13: 3400 | AP13: DaDef | AQ13: 8000 | AS13: 800 | AT13: 4800 | AU13: 1100 | AV13: 2880 | AX13: 36650 | AY13: 29290
A14: 5500 | B14: --- | C14: --- | D14: --- | E14: --- | F14: --- | G14: --- | I14: 0 | J14: 0 | K14: 0 | L14: 0 | M14: 0 | N14: 0 | O14: =(VALORI!B$3 * 'PASTA CORTA - TCM100'!I14) + (VALORI!B$4 * 'PASTA CORTA - TCM100'!J14) + (VALORI!B$4 * 'PASTA CORTA - TCM100'!K14) + (VALORI!B$5 * 'PASTA CORTA - TCM100'!L14) + (VALORI!B$6 * 'PASTA CORTA - TCM100'!M14) + (VALORI!B$7 * 'PASTA CORTA - TCM100'!N14) -> 0 | P14: =(O14*25%)+O14 -> 0 | Q14: 0 | R14: =(Q14*20%)+Q14 -> 0 | T14: =O14+Q14 -> 0 | U14: =P14+R14 -> 0 | V14: +
A15: 6000 | B15: FA.ST. 245.2-670 TV | C15: LANDUCCI/NICCOLAI | D15: TMD 19 | E15: Z 1100 GP STD | F15: TCM-L-100 23,4/11 | G15: RMN_L-F 6/1-1 | I15: 110 | J15: 50 | K15: 50 | L15: 620 | M15: 70 | N15: 100 | O15: =(VALORI!B$3 * 'PASTA CORTA - TCM100'!I15) + (VALORI!B$4 * 'PASTA CORTA - TCM100'!J15) + (VALORI!B$4 * 'PASTA CORTA - TCM100'!K15) + (VALORI!B$5 * 'PASTA CORTA - TCM100'!L15) + (VALORI!B$6 * 'PASTA CORTA - TCM100'!M15) + (VALORI!B$7 * 'PASTA CORTA - TCM100'!N15) -> 31680 | P15: =(O15*25%)+O15 -> 39600 | Q15: 105165.06 | R15: =(Q15*20%)+Q15 -> 126198.07 | S15: A=5200 + B=5200 | T15: =O15+Q15 -> 136845.06 | U15: =P15+R15 -> 165798.07 | V15: + | W15: =(Q15*6%) -> 6309.9036 | X15: =(Q15*20%) -> 21033.012 | Y15: 12000 | Z15: =(Y15*65%)+Y15 -> 19800 | AA15: 3800 | AB15: 5500 | AC15: 1300 | AD15: 8000 | AE15: 2200 | AF15: 2800 | AG15: 1100 | AH15: 8000 | AI15: 4200 | AJ15: 2200 | AK15: 11000 | AL15: =(AK15*15%) -> 1650 | AM15: 720 | AN15: 2200 | AO15: 3400 | AP15: DaDef | AQ15: 8000 | AS15: 800 | AT15: 4800 | AU15: 1100 | AV15: 2880 | AX15: 36650 | AY15: 29290
A16: 8000 | B16: --- | C16: --- | D16: --- | F16: --- | G16: --- | I16: 0 | J16: 0 | K16: 0 | L16: 0 | M16: 0 | N16: 0 | O16: =(VALORI!B$3 * 'PASTA CORTA - TCM100'!I16) + (VALORI!B$4 * 'PASTA CORTA - TCM100'!J16) + (VALORI!B$4 * 'PASTA CORTA - TCM100'!K16) + (VALORI!B$5 * 'PASTA CORTA - TCM100'!L16) + (VALORI!B$6 * 'PASTA CORTA - TCM100'!M16) + (VALORI!B$7 * 'PASTA CORTA - TCM100'!N16) -> 0 | P16: =(O16*25%)+O16 -> 0 | Q16: 0 | R16: =(Q16*20%)+Q16 -> 0 | T16: =O16+Q16 -> 0 | U16: =P16+R16 -> 0 | V16: +
A17: 9000 | B17: --- | C17: --- | D17: --- | F17: --- | G17: --- | I17: 0 | J17: 0 | K17: 0 | L17: 0 | M17: 0 | N17: 0 | O17: =(VALORI!B$3 * 'PASTA CORTA - TCM100'!I17) + (VALORI!B$4 * 'PASTA CORTA - TCM100'!J17) + (VALORI!B$4 * 'PASTA CORTA - TCM100'!K17) + (VALORI!B$5 * 'PASTA CORTA - TCM100'!L17) + (VALORI!B$6 * 'PASTA CORTA - TCM100'!M17) + (VALORI!B$7 * 'PASTA CORTA - TCM100'!N17) -> 0 | P17: =(O17*25%)+O17 -> 0 | Q17: 0 | R17: =(Q17*20%)+Q17 -> 0 | T17: =O17+Q17 -> 0 | U17: =P17+R17 -> 0 | V17: + | AS17: 1600 | AT17: 4800 | AU17: 1100 | AV17: 2880 | AX17: 36650 | AY17: 29290
A18: 12000 | B18: --- | C18: --- | D18: --- | E18: --- | F18: --- | G18: --- | I18: 0 | J18: 0 | K18: 0 | L18: 0 | M18: 0 | N18: 0 | O18: =(VALORI!B$3 * 'PASTA CORTA - TCM100'!I18) + (VALORI!B$4 * 'PASTA CORTA - TCM100'!J18) + (VALORI!B$4 * 'PASTA CORTA - TCM100'!K18) + (VALORI!B$5 * 'PASTA CORTA - TCM100'!L18) + (VALORI!B$6 * 'PASTA CORTA - TCM100'!M18) + (VALORI!B$7 * 'PASTA CORTA - TCM100'!N18) -> 0 | P18: =(O18*25%)+O18 -> 0 | Q18: 0 | R18: =(Q18*20%)+Q18 -> 0 | T18: =O18+Q18 -> 0 | U18: =P18+R18 -> 0 | V18: + | AS18: 1600 | AT18: 4800 | AU18: 1100 | AV18: 2880 | AX18: 36650 | AY18: 29290
O30: Incremento Ore Attività | Q30: PLC h + | R30: DaDef | W30: 0 | X30: 0 | Y30: 0 | Z30: 0 | AA30: 0 | AB30: 0 | AC30: 4 | AD30: 8 | AE30: 8 | AF30: 8 | AG30: 8 | AH30: 0 | AI30: 8 | AJ30: 4 | AK30: 30 | AL30: 2 | AM30: 2 | AN30: 2 | AO30: 1 | AQ30: 0 | AS30: 8 | AT30: 16 | AU30: 6 | AV30: 6
Q31: HMI h+ | R31: DaDef | W31: 0 | X31: 0 | Y31: 0 | Z31: 0 | AA31: 0 | AB31: 0 | AC31: 8 | AD31: 8 | AE31: 8 | AF31: 8 | AG31: 8 | AH31: 0 | AI31: 8 | AJ31: 4 | AK31: 30 | AL31: 2 | AM31: 2 | AN31: 2 | AO31: 1 | AQ31: 0 | AS31: 8 | AT31: 16 | AU31: 6 | AV31: 6
Q32: SCH h + | R32: 30 | W32: 10 | X32: 30 | Y32: 8 | Z32: 8 | AA32: 8 | AB32: 2 | AC32: 6 | AD32: 8 | AE32: 10 | AF32: 10 | AG32: 10 | AH32: 4 | AI32: 8 | AJ32: 5 | AK32: 20 | AL32: 4 | AM32: 4 | AN32: 1 | AO32: 4 | AQ32: 15 | AS32: 8 | AT32: 16 | AU32: 6 | AV32: 6
Q33: OFF h + | R33: 90 | W33: 30 | X33: 90 | Y33: 24 | Z33: 24 | AA33: 20 | AB33: 1 | AC33: 4 | AD33: 50 | AE33: 10 | AF33: 5 | AG33: 5 | AH33: 0 | AI33: 24 | AJ33: 5 | AK33: 30 | AL33: 8 | AM33: 4 | AN33: 8 | AO33: 12 | AQ33: 3 | AS33: 20 | AT33: 50 | AU33: 20 | AV33: 20
O37: 44731 | P37: 10% dal 20/06 | Q37: 4% dal 2023 | R37: 3% dal 2024 | W37: Costo Materiale | X37: Costo Materiale | Y37: Costo Materiale | Z37: Costo Materiale | AA37: Costo Materiale | AB37: Costo Materiale | AC37: Costo Materiale | AD37: Costo Materiale | AE37: Costo Materiale | AF37: Costo Materiale | AG37: Costo Materiale | AH37: Costo Materiale | AI37: Costo Materiale | AJ37: Costo Materiale | AK37: Costo Materiale | AL37: Costo Materiale | AM37: Costo Materiale | AN37: Costo Materiale | AO37: Costo Materiale | AP37: Costo Materiale | AQ37: Costo Materiale
O38: 0 | P38: =(O38*10%)+O38 -> 0 | Q38: =(P38*4%)+P38 -> 0 | R38: =(Q38*3%)+Q38 -> 0 | W38: =IF(W3>0, W3-(W$30*VALORI!$B$4)-(W$31*VALORI!$B$4)-(W$32*VALORI!$B$3)-(W$33*VALORI!$B$5),0) -> 0 | X38: =IF(X3>0, X3-(X$30*VALORI!$B$4)-(X$31*VALORI!$B$4)-(X$32*VALORI!$B$3)-(X$33*VALORI!$B$5),0) -> 0 | Y38: =IF(Y3>0, Y3-(Y$30*VALORI!$B$4)-(Y$31*VALORI!$B$4)-(Y$32*VALORI!$B$3)-(Y$33*VALORI!$B$5),0) -> 0 | Z38: =IF(Z3>0, Z3-(Z$30*VALORI!$B$4)-(Z$31*VALORI!$B$4)-(Z$32*VALORI!$B$3)-(Z$33*VALORI!$B$5),0) -> 0 | AA38: =IF(AA3>0, AA3-(AA$30*VALORI!$B$4)-(AA$31*VALORI!$B$4)-(AA$32*VALORI!$B$3)-(AA$33*VALORI!$B$5),0) -> 0 | AB38: =IF(AB3>0, AB3-(AB$30*VALORI!$B$4)-(AB$31*VALORI!$B$4)-(AB$32*VALORI!$B$3)-(AB$33*VALORI!$B$5),0) -> 0 | AC38: =IF(AC3>0, AC3-(AC$30*VALORI!$B$4)-(AC$31*VALORI!$B$4)-(AC$32*VALORI!$B$3)-(AC$33*VALORI!$B$5),0) -> 0 | AD38: =IF(AD3>0, AD3-(AD$30*VALORI!$B$4)-(AD$31*VALORI!$B$4)-(AD$32*VALORI!$B$3)-(AD$33*VALORI!$B$5),0) -> 0 | ... AQ38: =IF(AQ3>0, AQ3-(AQ$30*VALORI!$B$4)-(AQ$31*VALORI!$B$4)-(AQ$32*VALORI!$B$3)-(AQ$33*VALORI!$B$5),0) -> 0
O39: 0 | P39: =(O39*10%)+O39 -> 0 | Q39: =(P39*4%)+P39 -> 0 | R39: =(Q39*3%)+Q39 -> 0 | W39: =IF(W4>0, W4-(W$30*VALORI!$B$4)-(W$31*VALORI!$B$4)-(W$32*VALORI!$B$3)-(W$33*VALORI!$B$5),0) -> 0 | X39: =IF(X4>0, X4-(X$30*VALORI!$B$4)-(X$31*VALORI!$B$4)-(X$32*VALORI!$B$3)-(X$33*VALORI!$B$5),0) -> 0 | Y39: =IF(Y4>0, Y4-(Y$30*VALORI!$B$4)-(Y$31*VALORI!$B$4)-(Y$32*VALORI!$B$3)-(Y$33*VALORI!$B$5),0) -> 0 | Z39: =IF(Z4>0, Z4-(Z$30*VALORI!$B$4)-(Z$31*VALORI!$B$4)-(Z$32*VALORI!$B$3)-(Z$33*VALORI!$B$5),0) -> 0 | AA39: =IF(AA4>0, AA4-(AA$30*VALORI!$B$4)-(AA$31*VALORI!$B$4)-(AA$32*VALORI!$B$3)-(AA$33*VALORI!$B$5),0) -> 0 | AB39: =IF(AB4>0, AB4-(AB$30*VALORI!$B$4)-(AB$31*VALORI!$B$4)-(AB$32*VALORI!$B$3)-(AB$33*VALORI!$B$5),0) -> 0 | AC39: =IF(AC4>0, AC4-(AC$30*VALORI!$B$4)-(AC$31*VALORI!$B$4)-(AC$32*VALORI!$B$3)-(AC$33*VALORI!$B$5),0) -> 0 | AD39: =IF(AD4>0, AD4-(AD$30*VALORI!$B$4)-(AD$31*VALORI!$B$4)-(AD$32*VALORI!$B$3)-(AD$33*VALORI!$B$5),0) -> 0 | ... AQ39: =IF(AQ4>0, AQ4-(AQ$30*VALORI!$B$4)-(AQ$31*VALORI!$B$4)-(AQ$32*VALORI!$B$3)-(AQ$33*VALORI!$B$5),0) -> 0
O40: 0 | P40: =(O40*10%)+O40 -> 0 | Q40: =(P40*4%)+P40 -> 0 | R40: =(Q40*3%)+Q40 -> 0 | W40: =IF(W5>0, W5-(W$30*VALORI!$B$4)-(W$31*VALORI!$B$4)-(W$32*VALORI!$B$3)-(W$33*VALORI!$B$5),0) -> 0 | X40: =IF(X5>0, X5-(X$30*VALORI!$B$4)-(X$31*VALORI!$B$4)-(X$32*VALORI!$B$3)-(X$33*VALORI!$B$5),0) -> 0 | Y40: =IF(Y5>0, Y5-(Y$30*VALORI!$B$4)-(Y$31*VALORI!$B$4)-(Y$32*VALORI!$B$3)-(Y$33*VALORI!$B$5),0) -> 0 | Z40: =IF(Z5>0, Z5-(Z$30*VALORI!$B$4)-(Z$31*VALORI!$B$4)-(Z$32*VALORI!$B$3)-(Z$33*VALORI!$B$5),0) -> 0 | AA40: =IF(AA5>0, AA5-(AA$30*VALORI!$B$4)-(AA$31*VALORI!$B$4)-(AA$32*VALORI!$B$3)-(AA$33*VALORI!$B$5),0) -> 0 | AB40: =IF(AB5>0, AB5-(AB$30*VALORI!$B$4)-(AB$31*VALORI!$B$4)-(AB$32*VALORI!$B$3)-(AB$33*VALORI!$B$5),0) -> 0 | AC40: =IF(AC5>0, AC5-(AC$30*VALORI!$B$4)-(AC$31*VALORI!$B$4)-(AC$32*VALORI!$B$3)-(AC$33*VALORI!$B$5),0) -> 0 | AD40: =IF(AD5>0, AD5-(AD$30*VALORI!$B$4)-(AD$31*VALORI!$B$4)-(AD$32*VALORI!$B$3)-(AD$33*VALORI!$B$5),0) -> 0 | ... AQ40: =IF(AQ5>0, AQ5-(AQ$30*VALORI!$B$4)-(AQ$31*VALORI!$B$4)-(AQ$32*VALORI!$B$3)-(AQ$33*VALORI!$B$5),0) -> 0
O41: 0 | P41: =(O41*10%)+O41 -> 0 | Q41: =(P41*4%)+P41 -> 0 | R41: =(Q41*3%)+Q41 -> 0 | W41: =IF(W6>0, W6-(W$30*VALORI!$B$4)-(W$31*VALORI!$B$4)-(W$32*VALORI!$B$3)-(W$33*VALORI!$B$5),0) -> 0 | X41: =IF(X6>0, X6-(X$30*VALORI!$B$4)-(X$31*VALORI!$B$4)-(X$32*VALORI!$B$3)-(X$33*VALORI!$B$5),0) -> 0 | Y41: =IF(Y6>0, Y6-(Y$30*VALORI!$B$4)-(Y$31*VALORI!$B$4)-(Y$32*VALORI!$B$3)-(Y$33*VALORI!$B$5),0) -> 0 | Z41: =IF(Z6>0, Z6-(Z$30*VALORI!$B$4)-(Z$31*VALORI!$B$4)-(Z$32*VALORI!$B$3)-(Z$33*VALORI!$B$5),0) -> 0 | AA41: =IF(AA6>0, AA6-(AA$30*VALORI!$B$4)-(AA$31*VALORI!$B$4)-(AA$32*VALORI!$B$3)-(AA$33*VALORI!$B$5),0) -> 0 | AB41: =IF(AB6>0, AB6-(AB$30*VALORI!$B$4)-(AB$31*VALORI!$B$4)-(AB$32*VALORI!$B$3)-(AB$33*VALORI!$B$5),0) -> 0 | AC41: =IF(AC6>0, AC6-(AC$30*VALORI!$B$4)-(AC$31*VALORI!$B$4)-(AC$32*VALORI!$B$3)-(AC$33*VALORI!$B$5),0) -> 0 | AD41: =IF(AD6>0, AD6-(AD$30*VALORI!$B$4)-(AD$31*VALORI!$B$4)-(AD$32*VALORI!$B$3)-(AD$33*VALORI!$B$5),0) -> 0 | ... AQ41: =IF(AQ6>0, AQ6-(AQ$30*VALORI!$B$4)-(AQ$31*VALORI!$B$4)-(AQ$32*VALORI!$B$3)-(AQ$33*VALORI!$B$5),0) -> 0
